Workbook

Sheet Setup
A1: # | B1: Player | C1: HC Source | D1: Index | E1: Handicap | F1: Adjustment1 | G1: Penalty | H1: 9-Hole HC | I1: 18-Hole HC | J1: Par 3 HC | K1: Paid | L1: Adjustment | M1: Penalty | R1: =L2 -> Lifetime | S1: =L4 -> Rookie | T1: =L6 -> Champ | U1: =L8 -> Double Deuce | V1: =L10 -> 2X Champ | W1: =L12 -> 3X Champ | X1: Total
A2: 1 | B2: Mil | D2: 13.5 | E2: =D2*(1+$C$36) -> 14.885841 | F2: Champ | G2: =IF(SUM(R2:W2)<0,SUM(R2:W2),0) -> -3 | H2: =IF((E2+G2)>C$37,(0.5*C$37),(E2+G2)/2) -> 5.9429204 | I2: =IF((E2+G2)>C$37,C$37,E2+G2) -> 11.885841 | J2: =ROUND(I2*0.375,0) -> 4 | K2: 100 | L2: Lifetime | M2: -1 | O2: =Scramble!B6 -> Gerald C | P2: =Scramble!A10 -> 18.025 | R2: =IF($F2=R$1,$M$2,"") | S2: =IF($F2=S$1,$E2*$M$4,"") | T2: =IF($F2=T$1,$M$6,"") -> -3 | U2: =IF($F2=U$1,$E2*$M$8,"") | V2: =IF($F2=V$1,$M$10,"") | W2: =IF($F2=W$1,$M$12,"") | X2: =SUM(R2:W2) -> -3
B3: =ROUND(H2,0) -> 6 | R3: =IF($F3=R$1,$M$2,"") | S3: =IF($F3=S$1,$E3*$M$4,"") | T3: =IF($F3=T$1,$M$6,"") | U3: =IF($F3=U$1,$E3*$M$8,"") | V3: =IF($F3=V$1,$M$10,"") | X3: =SUM(R3:W3) -> 0
A4: 2 | B4: John | D4: 12.6 | E4: =D4*(1+$C$36) -> 13.893451 | G4: =IF(SUM(R4:W4)<0,SUM(R4:W4),0) -> 0 | H4: =IF((E4+G4)>C$37,(0.5*C$37),(E4+G4)/2) -> 6.9467257 | I4: =IF((E4+G4)>C$37,C$37,E4+G4) -> 13.893451 | J4: =ROUND(I4*0.375,0) -> 5 | K4: 100 | L4: Rookie | M4: -0.2 | O4: =Scramble!B8 -> Rick | R4: =IF($F4=R$1,$M$2,"") | S4: =IF($F4=S$1,$E4*$M$4,"") | T4: =IF($F4=T$1,$M$6,"") | U4: =IF($F4=U$1,$E4*$M$8,"") | V4: =IF($F4=V$1,$M$10,"") | W4: =IF($F4=W$1,$M$12,"") | X4: =SUM(R4:W4) -> 0
B5: =ROUND(H4,0) -> 7 | R5: =IF($F5=R$1,$M$2,"") | S5: =IF($F5=S$1,$E5*$M$4,"") | T5: =IF($F5=T$1,$M$6,"") | U5: =IF($F5=U$1,$E5*$M$8,"") | V5: =IF($F5=V$1,$M$10,"") | X5: =SUM(R5:W5) -> 0
A6: 3 | B6: Brian P | D6: 13.5 | E6: =D6*(1+$C$36) -> 14.885841 | F6: Rookie | G6: =IF(SUM(R6:W6)<0,SUM(R6:W6),0) -> -2.9771681 | H6: =IF((E6+G6)>C$37,(0.5*C$37),(E6+G6)/2) -> 5.9543363 | I6: =IF((E6+G6)>C$37,C$37,E6+G6) -> 11.908673 | J6: =ROUND(I6*0.375,0) -> 4 | K6: 100 | L6: Champ | M6: -3 | O6: =Scramble!B10 -> Patrick | R6: =IF($F6=R$1,$M$2,"") | S6: =IF($F6=S$1,$E6*$M$4,"") -> -2.9771681 | T6: =IF($F6=T$1,$M$6,"") | U6: =IF($F6=U$1,$E6*$M$8,"") | V6: =IF($F6=V$1,$M$10,"") | W6: =IF($F6=W$1,$M$12,"") | X6: =SUM(R6:W6) -> -2.9771681
B7: =ROUND(H6,0) -> 6 | R7: =IF($F7=R$1,$M$2,"") | S7: =IF($F7=S$1,$E7*$M$4,"") | T7: =IF($F7=T$1,$M$6,"") | U7: =IF($F7=U$1,$E7*$M$8,"") | V7: =IF($F7=V$1,$M$10,"") | X7: =SUM(R7:W7) -> 0
A8: 4 | B8: Pat | D8: 11.7 | E8: =D8*(1+$C$36) -> 12.901062 | G8: =IF(SUM(R8:W8)<0,SUM(R8:W8),0) -> 0 | H8: =IF((E8+G8)>C$37,(0.5*C$37),(E8+G8)/2) -> 6.450531 | I8: =IF((E8+G8)>C$37,C$37,E8+G8) -> 12.901062 | J8: =ROUND(I8*0.375,0) -> 5 | K8: 100 | L8: Double Deuce | M8: -0.15 | O8: =Scramble!B12 -> Brian P | R8: =IF($F8=R$1,$M$2,"") | S8: =IF($F8=S$1,$E8*$M$4,"") | T8: =IF($F8=T$1,$M$6,"") | U8: =IF($F8=U$1,$E8*$M$8,"") | V8: =IF($F8=V$1,$M$10,"") | W8: =IF($F8=W$1,$M$12,"") | X8: =SUM(R8:W8) -> 0
B9: =ROUND(H8,0) -> 6 | R9: =IF($F9=R$1,$M$2,"") | S9: =IF($F9=S$1,$E9*$M$4,"") | T9: =IF($F9=T$1,$M$6,"") | U9: =IF($F9=U$1,$E9*$M$8,"") | V9: =IF($F9=V$1,$M$10,"") | X9: =SUM(R9:W9) -> 0
A10: 5 | B10: Rick | D10: 13.5 | E10: =D10*(1+$C$36) -> 14.885841 | G10: =IF(SUM(R10:W10)<0,SUM(R10:W10),0) -> 0 | H10: =IF((E10+G10)>C$37,(0.5*C$37),(E10+G10)/2) -> 7.4429204 | I10: =IF((E10+G10)>C$37,C$37,E10+G10) -> 14.885841 | J10: =ROUND(I10*0.375,0) -> 6 | K10: 100 | L10: 2X Champ | M10: -4 | O10: =Scramble!B14 -> Pat | P10: =Scramble!A18 -> 18.25 | R10: =IF($F10=R$1,$M$2,"") | S10: =IF($F10=S$1,$E10*$M$4,"") | T10: =IF($F10=T$1,$M$6,"") | U10: =IF($F10=U$1,$E10*$M$8,"") | V10: =IF($F10=V$1,$M$10,"") | W10: =IF($F10=W$1,$M$12,"") | X10: =SUM(R10:W10) -> 0
B11: =ROUND(H10,0) -> 7 | R11: =IF($F11=R$1,$M$2,"") | S11: =IF($F11=S$1,$E11*$M$4,"") | T11: =IF($F11=T$1,$M$6,"") | U11: =IF($F11=U$1,$E11*$M$8,"") | V11: =IF($F11=V$1,$M$10,"") | X11: =SUM(R11:W11) -> 0
A12: 6 | B12: Keith | D12: 29.8 | E12: =D12*(1+$C$36) -> 32.859115 | G12: =IF(SUM(R12:W12)<0,SUM(R12:W12),0) -> 0 | H12: =IF((E12+G12)>C$37,(0.5*C$37),(E12+G12)/2) -> 16 | I12: =IF((E12+G12)>C$37,C$37,E12+G12) -> 32 | J12: =ROUND(I12*0.375,0) -> 12 | K12: 100 | L12: 3X Champ | M12: -5 | O12: =Scramble!B16 -> Hunter | R12: =IF($F12=R$1,$M$2,"") | S12: =IF($F12=S$1,$E12*$M$4,"") | T12: =IF($F12=T$1,$M$6,"") | U12: =IF($F12=U$1,$E12*$M$8,"") | V12: =IF($F12=V$1,$M$10,"") | W12: =IF($F12=W$1,$M$12,"") | X12: =SUM(R12:W12) -> 0
B13: =ROUND(H12,0) -> 16 | R13: =IF($F13=R$1,$M$2,"") | S13: =IF($F13=S$1,$E13*$M$4,"") | T13: =IF($F13=T$1,$M$6,"") | U13: =IF($F13=U$1,$E13*$M$8,"") | V13: =IF($F13=V$1,$M$10,"") | X13: =SUM(R13:W13) -> 0
A14: 7 | B14: Tony W | D14: 22.1 | E14: =D14*(1+$C$36) -> 24.368673 | F14: Rookie | G14: =IF(SUM(R14:W14)<0,SUM(R14:W14),0) -> -4.8737345 | H14: =IF((E14+G14)>C$37,(0.5*C$37),(E14+G14)/2) -> 9.747469 | I14: =IF((E14+G14)>C$37,C$37,E14+G14) -> 19.494938 | J14: =ROUND(I14*0.375,0) -> 7 | K14: 100 | O14: =Scramble!B18 -> Bob | R14: =IF($F14=R$1,$M$2,"") | S14: =IF($F14=S$1,$E14*$M$4,"") -> -4.8737345 | T14: =IF($F14=T$1,$M$6,"") | U14: =IF($F14=U$1,$E14*$M$8,"") | V14: =IF($F14=V$1,$M$10,"") | W14: =IF($F14=W$1,$M$12,"") | X14: =SUM(R14:W14) -> -4.8737345
B15: =ROUND(H14,0) -> 10 | R15: =IF($F15=R$1,$M$2,"") | S15: =IF($F15=S$1,$E15*$M$4,"") | T15: =IF($F15=T$1,$M$6,"") | U15: =IF($F15=U$1,$E15*$M$8,"") | V15: =IF($F15=V$1,$M$10,"") | X15: =SUM(R15:W15) -> 0
A16: 8 | B16: Manny | D16: 25.2 | E16: =D16*(1+$C$36) -> 27.786903 | G16: =IF(SUM(R16:W16)<0,SUM(R16:W16),0) -> 0 | H16: =IF((E16+G16)>C$37,(0.5*C$37),(E16+G16)/2) -> 13.893451 | I16: =IF((E16+G16)>C$37,C$37,E16+G16) -> 27.786903 | J16: =ROUND(I16*0.375,0) -> 10 | K16: 100 | O16: =Scramble!B20 -> Keith | R16: =IF($F16=R$1,$M$2,"") | S16: =IF($F16=S$1,$E16*$M$4,"") | T16: =IF($F16=T$1,$M$6,"") | U16: =IF($F16=U$1,$E16*$M$8,"") | V16: =IF($F16=V$1,$M$10,"") | W16: =IF($F16=W$1,$M$12,"") | X16: =SUM(R16:W16) -> 0
B17: =ROUND(H16,0) -> 14 | R17: =IF($F17=R$1,$M$2,"") | S17: =IF($F17=S$1,$E17*$M$4,"") | T17: =IF($F17=T$1,$M$6,"") | U17: =IF($F17=U$1,$E17*$M$8,"") | V17: =IF($F17=V$1,$M$10,"") | X17: =SUM(R17:W17) -> 0
A18: 9 | B18: Tommy | D18: 9.4 | E18: =D18*(1+$C$36) -> 10.364956 | G18: =IF(SUM(R18:W18)<0,SUM(R18:W18),0) -> 0 | H18: =IF((E18+G18)>C$37,(0.5*C$37),(E18+G18)/2) -> 5.1824779 | I18: =IF((E18+G18)>C$37,C$37,E18+G18) -> 10.364956 | J18: =ROUND(I18*0.375,0) -> 4 | K18: 100 | O18: =Scramble!B22 -> John | P18: =Scramble!A26 -> 17.725 | R18: =IF($F18=R$1,$M$2,"") | S18: =IF($F18=S$1,$E18*$M$4,"") | T18: =IF($F18=T$1,$M$6,"") | U18: =IF($F18=U$1,$E18*$M$8,"") | V18: =IF($F18=V$1,$M$10,"") | W18: =IF($F18=W$1,$M$12,"") | X18: =SUM(R18:W18) -> 0
B19: =ROUND(H18,0) -> 5 | R19: =IF($F19=R$1,$M$2,"") | S19: =IF($F19=S$1,$E19*$M$4,"") | T19: =IF($F19=T$1,$M$6,"") | U19: =IF($F19=U$1,$E19*$M$8,"") | V19: =IF($F19=V$1,$M$10,"") | X19: =SUM(R19:W19) -> 0
A20: 10 | B20: Dave | D20: 8.8 | E20: =D20*(1+$C$36) -> 9.7033628 | G20: =IF(SUM(R20:W20)<0,SUM(R20:W20),0) -> 0 | H20: =IF((E20+G20)>C$37,(0.5*C$37),(E20+G20)/2) -> 4.8516814 | I20: =IF((E20+G20)>C$37,C$37,E20+G20) -> 9.7033628 | J20: =ROUND(I20*0.375,0) -> 4 | K20: 100 | O20: =Scramble!B24 -> Manny | R20: =IF($F20=R$1,$M$2,"") | S20: =IF($F20=S$1,$E20*$M$4,"") | T20: =IF($F20=T$1,$M$6,"") | U20: =IF($F20=U$1,$E20*$M$8,"") | V20: =IF($F20=V$1,$M$10,"") | W20: =IF($F20=W$1,$M$12,"") | X20: =SUM(R20:W20) -> 0
B21: =ROUND(H20,0) -> 5 | R21: =IF($F21=R$1,$M$2,"") | S21: =IF($F21=S$1,$E21*$M$4,"") | T21: =IF($F21=T$1,$M$6,"") | U21: =IF($F21=U$1,$E21*$M$8,"") | V21: =IF($F21=V$1,$M$10,"") | X21: =SUM(R21:W21) -> 0
A22: 11 | B22: Hunter | D22: 13.4 | E22: =D22*(1+$C$36) -> 14.775575 | G22: =IF(SUM(R22:W22)<0,SUM(R22:W22),0) -> 0 | H22: =IF((E22+G22)>C$37,(0.5*C$37),(E22+G22)/2) -> 7.3877876 | I22: =IF((E22+G22)>C$37,C$37,E22+G22) -> 14.775575 | J22: =ROUND(I22*0.375,0) -> 6 | K22: 100 | O22: =Scramble!B26 -> Brian S | R22: =IF($F22=R$1,$M$2,"") | S22: =IF($F22=S$1,$E22*$M$4,"") | T22: =IF($F22=T$1,$M$6,"") | U22: =IF($F22=U$1,$E22*$M$8,"") | V22: =IF($F22=V$1,$M$10,"") | W22: =IF($F22=W$1,$M$12,"") | X22: =SUM(R22:W22) -> 0
B23: =ROUND(H22,0) -> 7 | R23: =IF($F23=R$1,$M$2,"") | S23: =IF($F23=S$1,$E23*$M$4,"") | T23: =IF($F23=T$1,$M$6,"") | U23: =IF($F23=U$1,$E23*$M$8,"") | V23: =IF($F23=V$1,$M$10,"") | X23: =SUM(R23:W23) -> 0
A24: 12 | B24: Gerald C | D24: 27.6 | E24: =D24*(1+$C$36) -> 30.433274 | F24: Rookie | G24: =IF(SUM(R24:W24)<0,SUM(R24:W24),0) -> -6.0866549 | H24: =IF((E24+G24)>C$37,(0.5*C$37),(E24+G24)/2) -> 12.17331 | I24: =IF((E24+G24)>C$37,C$37,E24+G24) -> 24.346619 | J24: =ROUND(I24*0.375,0) -> 9 | K24: 100 | O24: =Scramble!B28 -> Tommy | R24: =IF($F24=R$1,$M$2,"") | S24: =IF($F24=S$1,$E24*$M$4,"") -> -6.0866549 | T24: =IF($F24=T$1,$M$6,"") | U24: =IF($F24=U$1,$E24*$M$8,"") | V24: =IF($F24=V$1,$M$10,"") | W24: =IF($F24=W$1,$M$12,"") | X24: =SUM(R24:W24) -> -6.0866549
B25: =ROUND(H24,0) -> 12 | R25: =IF($F25=R$1,$M$2,"") | S25: =IF($F25=S$1,$E25*$M$4,"") | T25: =IF($F25=T$1,$M$6,"") | U25: =IF($F25=U$1,$E25*$M$8,"") | V25: =IF($F25=V$1,$M$10,"") | X25: =SUM(R25:W25) -> 0
A26: 13 | B26: Bob | D26: 18.1 | E26: =D26*(1+$C$36) -> 19.958053 | G26: =IF(SUM(R26:W26)<0,SUM(R26:W26),0) -> 0 | H26: =IF((E26+G26)>C$37,(0.5*C$37),(E26+G26)/2) -> 9.9790265 | I26: =IF((E26+G26)>C$37,C$37,E26+G26) -> 19.958053 | J26: =ROUND(I26*0.375,0) -> 7 | K26: 100 | O26: =Scramble!B30 -> Mil | P26: =Scramble!A34 -> 17.875 | R26: =IF($F26=R$1,$M$2,"") | S26: =IF($F26=S$1,$E26*$M$4,"") | T26: =IF($F26=T$1,$M$6,"") | U26: =IF($F26=U$1,$E26*$M$8,"") | V26: =IF($F26=V$1,$M$10,"") | W26: =IF($F26=W$1,$M$12,"") | X26: =SUM(R26:W26) -> 0
B27: =ROUND(H26,0) -> 10 | R27: =IF($F27=R$1,$M$2,"") | S27: =IF($F27=S$1,$E27*$M$4,"") | T27: =IF($F27=T$1,$M$6,"") | U27: =IF($F27=U$1,$E27*$M$8,"") | V27: =IF($F27=V$1,$M$10,"") | X27: =SUM(R27:W27) -> 0
A28: 14 | B28: Patrick | D28: 17.5 | E28: =D28*(1+$C$36) -> 19.29646 | F28: Rookie | G28: =IF(SUM(R28:W28)<0,SUM(R28:W28),0) -> -3.859292 | H28: =IF((E28+G28)>C$37,(0.5*C$37),(E28+G28)/2) -> 7.7185841 | I28: =IF((E28+G28)>C$37,C$37,E28+G28) -> 15.437168 | J28: =ROUND(I28*0.375,0) -> 6 | K28: 100 | O28: =Scramble!B32 -> Dave | R28: =IF($F28=R$1,$M$2,"") | S28: =IF($F28=S$1,$E28*$M$4,"") -> -3.859292 | T28: =IF($F28=T$1,$M$6,"") | U28: =IF($F28=U$1,$E28*$M$8,"") | V28: =IF($F28=V$1,$M$10,"") | W28: =IF($F28=W$1,$M$12,"") | X28: =SUM(R28:W28) -> -3.859292
B29: =ROUND(H28,0) -> 8 | R29: =IF($F29=R$1,$M$2,"") | S29: =IF($F29=S$1,$E29*$M$4,"") | T29: =IF($F29=T$1,$M$6,"") | U29: =IF($F29=U$1,$E29*$M$8,"") | V29: =IF($F29=V$1,$M$10,"") | X29: =SUM(R29:W29) -> 0
A30: 15 | B30: Brian S | D30: 23.7 | E30: =D30*(1+$C$36) -> 26.13292 | G30: =IF(SUM(R30:W30)<0,SUM(R30:W30),0) -> 0 | H30: =IF((E30+G30)>C$37,(0.5*C$37),(E30+G30)/2) -> 13.06646 | I30: =IF((E30+G30)>C$37,C$37,E30+G30) -> 26.13292 | J30: =ROUND(I30*0.375,0) -> 10 | K30: 100 | O30: =Scramble!B34 -> Tony W | R30: =IF($F30=R$1,$M$2,"") | S30: =IF($F30=S$1,$E30*$M$4,"") | T30: =IF($F30=T$1,$M$6,"") | U30: =IF($F30=U$1,$E30*$M$8,"") | V30: =IF($F30=V$1,$M$10,"") | W30: =IF($F30=W$1,$M$12,"") | X30: =SUM(R30:W30) -> 0
B31: =ROUND(H30,0) -> 13 | R31: =IF($F31=R$1,$M$2,"") | S31: =IF($F31=S$1,$E31*$M$4,"") | T31: =IF($F31=T$1,$M$6,"") | U31: =IF($F31=U$1,$E31*$M$8,"") | V31: =IF($F31=V$1,$M$10,"") | X31: =SUM(R31:W31) -> 0
A32: 16 | B32: Chris | D32: 27.1 | E32: =D32*(1+$C$36) -> 29.881947 | G32: =IF(SUM(R32:W32)<0,SUM(R32:W32),0) -> 0 | H32: =IF((E32+G32)>C$37,(0.5*C$37),(E32+G32)/2) -> 14.940973 | I32: =IF((E32+G32)>C$37,C$37,E32+G32) -> 29.881947 | J32: =ROUND(I32*0.375,0) -> 11 | K32: 100 | O32: =Scramble!B36 -> Chris | R32: =IF($F32=R$1,$M$2,"") | S32: =IF($F32=S$1,$E32*$M$4,"") | T32: =IF($F32=T$1,$M$6,"") | U32: =IF($F32=U$1,$E32*$M$8,"") | V32: =IF($F32=V$1,$M$10,"") | W32: =IF($F32=W$1,$M$12,"") | X32: =SUM(R32:W32) -> 0
B33: =ROUND(H32,0) -> 15 | R33: =IF($F33=R$1,$M$2,"") | S33: =IF($F33=S$1,$E33*$M$4,"") | T33: =IF($F33=T$1,$M$6,"") | U33: =IF($F33=U$1,$E33*$M$8,"") | V33: =IF($F33=V$1,$M$10,"") | X33: =SUM(R33:W33) -> 0
R34: =IF($F34=R$1,$M$2,"") | T34: =IF($F34=T$1,$M$6,"") | U34: =IF($F34=U$1,$D34*$M$8,"") | V34: =IF($F34=V$1,$M$10,"")
O35: Avg | P35: =AVERAGE(D2:D32) -> 17.96875 | R35: =IF($E35=R$1,$M$2,"") | T35: =IF($E35=T$1,$M$6,"") | U35: =IF($E35=U$1,$D35*$M$8,"") | V35: =IF($E35=V$1,$M$10,"")
B36: Index to HC Conversion | C36: =(F36/F37)-1 -> 0.10265487 | E36: Avg Course Slope | F36: =AVERAGE(Courses!A11,Courses!A21,Courses!A31,Courses!A41,Courses!A62) -> 124.6 | V36: =IF($E36=V$1,$M$10,"")
B37: Max Handicap | C37: 32 | E37: Avg Slope | F37: 113
B41: Total | C41: =SUM(K2:K33)-SUM(C42:C45)-(SUM(F41:F45)*5) -> 0 | E41: Long Drive | F41: 20
B42: Winner | C42: 700 | E42: Closest to Pin | F42: 20
B43: 2nd Place | C43: 350 | E43: Long Putt | F43: 20
...

Sheet Courses
B1: Long Drive
B2: Closest to Pin
B3: Long Putt
A5: Eagle Mountain
A6: Tees | B6: Front 9 | C6: 1 | D6: 2 | E6: 3 | F6: 4 | G6: 5 | H6: 6 | I6: 7 | J6: 8 | K6: 9
A7: Green | B7: Par | C7: 5 | D7: 4 | E7: 3 | F7: 5 | G7: 3 | H7: 4 | I7: 4 | J7: 3 | K7: 4 | L7: =SUM(C7:K7) -> 35
A8: Yardage | B8: Handicap | C8: 11 | D8: 5 | E8: 9 | F8: 13 | G8: 15 | H8: 7 | I8: 1 | J8: 17 | K8: 3
A9: 6269
A10: Slope | B10: Back 9 | C10: 10 | D10: 11 | E10: 12 | F10: 13 | G10: 14 | H10: 15 | I10: 16 | J10: 17 | K10: 18
A11: 127 | B11: Par | C11: 5 | D11: 4 | E11: 5 | F11: 3 | G11: 4 | H11: 3 | I11: 4 | J11: 4 | K11: 4 | L11: =SUM(C11:K11) -> 36
B12: Handicap | C12: 12 | D12: 4 | E12: 14 | F12: 10 | G12: 2 | H12: 18 | I12: 8 | J12: 6 | K12: 16
A15: Wekopa Cholla
A16: Tees | B16: Front 9 | C16: 1 | D16: 2 | E16: 3 | F16: 4 | G16: 5 | H16: 6 | I16: 7 | J16: 8 | K16: 9
A17: White | B17: Par | C17: 4 | D17: 5 | E17: 3 | F17: 4 | G17: 3 | H17: 4 | I17: 4 | J17: 5 | K17: 4 | L17: =SUM(C17:K17) -> 36
A18: Yardage | B18: Handicap | C18: 13 | D18: 3 | E18: 17 | F18: 9 | G18: 15 | H18: 7 | I18: 11 | J18: 1 | K18: 5
A19: 6114
A20: Slope | B20: Back 9 | C20: 10 | D20: 11 | E20: 12 | F20: 13 | G20: 14 | H20: 15 | I20: 16 | J20: 17 | K20: 18
A21: 119 | B21: Par | C21: 5 | D21: 3 | E21: 4 | F21: 4 | G21: 3 | H21: 4 | I21: 4 | J21: 5 | K21: 4 | L21: =SUM(C21:K21) -> 36
B22: Handicap | C22: 4 | D22: 16 | E22: 10 | F22: 12 | G22: 18 | H22: 14 | I22: 6 | J22: 2 | K22: 8
A25: Wekopa Saguaro
A26: Tees | B26: Front 9 | C26: 1 | D26: 2 | E26: 3 | F26: 4 | G26: 5 | H26: 6 | I26: 7 | J26: 8 | K26: 9
A27: White | B27: Par | C27: 4 | D27: 4 | E27: 4 | F27: 5 | G27: 3 | H27: 4 | I27: 4 | J27: 5 | K27: 3 | L27: =SUM(C27:K27) -> 36
A28: Yardage | B28: Handicap | C28: 5 | D28: 11 | E28: 9 | F28: 1 | G28: 15 | H28: 7 | I28: 13 | J28: 3 | K28: 9 | L28: 17
A29: 6252
A30: Slope | B30: Back 9 | C30: 10 | D30: 11 | E30: 12 | F30: 13 | G30: 14 | H30: 15 | I30: 16 | J30: 17 | K30: 18
A31: 125 | B31: Par | C31: 4 | D31: 3 | E31: 4 | F31: 4 | G31: 5 | H31: 3 | I31: 4 | J31: 4 | K31: 4 | L31: =SUM(C31:K31) -> 35
B32: Handicap | C32: 8 | D32: 14 | E32: 2 | F32: 6 | G32: 12 | H32: 18 | I32: 16 | J32: 4 | K32: 10
A35: Kierland A/M
A36: Tees | B36: Front 9 | C36: 1 | D36: 2 | E36: 3 | F36: 4 | G36: 5 | H36: 6 | I36: 7 | J36: 8 | K36: 9
A37: Copper | B37: Par | C37: 4 | D37: 4 | E37: 3 | F37: 4 | G37: 3 | H37: 4 | I37: 5 | J37: 4 | K37: 5 | L37: =SUM(C37:K37) -> 36
A38: Yardage | B38: Handicap | C38: 1 | D38: 5 | E38: 17 | F38: 7 | G38: 13 | H38: 11 | I38: 15 | J38: 9 | K38: 3
A39: 6319
A40: Slope | B40: Back 9 | C40: 10 | D40: 11 | E40: 12 | F40: 13 | G40: 14 | H40: 15 | I40: 16 | J40: 17 | K40: 18
A41: 123 | B41: Par | C41: 5 | D41: 4 | E41: 4 | F41: 3 | G41: 5 | H41: 3 | I41: 4 | J41: 3 | K41: 5 | L41: =SUM(C41:K41) -> 36
B42: Handicap | C42: 16 | D42: 8 | E42: 4 | F42: 18 | G42: 2 | H42: 12 | I42: 10 | J42: 14 | K42: 6
A44: PD Fazio - Replay
A45: Tees | B45: Front 9 | C45: 1 | D45: 2 | E45: 3 | F45: 4 | G45: 5 | H45: 6 | I45: 7 | J45: 8 | K45: 9
A46: White | B46: Par | C46: 4 | D46: 5 | E46: 4 | F46: 3 | G46: 4 | H46: 3 | I46: 4 | J46: 4 | K46: 4 | L46: =SUM(C46:K46) -> 35
A47: Yardage | B47: Handicap | C47: 3 | D47: 11 | E47: 9 | F47: 15 | G47: 7 | H47: 17 | I47: 5 | J47: 1 | K47: 13
A50: Kierland
...

Sheet Matchups
C1: Day 1 | D1: Day 2A | E1: Day 2B | F1: Day 3 | G1: Scramble
C2: =Courses!A5 -> Eagle Mountain | D2: =Courses!A15 -> Wekopa Cholla | E2: =Courses!A25 -> Wekopa Saguaro | F2: =Courses!A35 -> Kierland A/M | G2: =Courses!A50 -> Kierland | J2: Course | K2: Long Drive | L2: Closest to Pin | M2: Longest Putt
A3: GROUP 1 | C3: =Setup!B2 -> Mil | D3: =C11 -> Rick | E3: =C5 -> John | F3: =C21 -> Dave | G3: =C25 -> Gerald C | J3: =C2 -> Eagle Mountain | K3: 10 | L3: 13 | M3: 18
C4: =Setup!B3 -> 6 | D4: =C12 -> 7 | E4: =C6 -> 7 | F4: =C22 -> 5 | G4: =C26 -> 12
C5: =Setup!B4 -> John | D5: =C3 -> Mil | E5: =C11 -> Rick | F5: =C11 -> Rick | G5: =F5 -> Rick | J5: =D2 -> Wekopa Cholla | K5: 10 | L5: 5 | M5: 18
C6: =Setup!B5 -> 7 | D6: =C4 -> 6 | E6: =C12 -> 7 | F6: =C12 -> 7 | G6: =F6 -> 7
C7: =Setup!B6 -> Brian P | D7: =C19 -> Tommy | E7: =C23 -> Hunter | F7: =C31 -> Brian S | G7: =C29 -> Patrick | J7: =E2 -> Wekopa Saguaro | K7: 4 | L7: 9 | M7: 18
C8: =Setup!B7 -> 6 | D8: =C20 -> 5 | E8: =C24 -> 7 | F8: =C32 -> 13 | G8: =C30 -> 8
C9: =Setup!B8 -> Pat | D9: =C27 -> Bob | E9: =C33 -> Chris | F9: =C9 -> Pat | G9: =C7 -> Brian P | J9: =F2 -> Kierland A/M | K9: 9 | L9: 13 | M9: 18
C10: =Setup!B9 -> 6 | D10: =C28 -> 10 | E10: =C34 -> 15 | F10: =C10 -> 6 | G10: =C8 -> 6
A11: GROUP 2 | C11: =Setup!B10 -> Rick | D11: =C21 -> Dave | E11: =C27 -> Bob | F11: =C3 -> Mil | G11: =C9 -> Pat | J11: =Courses!A56 -> Troon N MNMT | K11: 11 | L11: 13 | M11: 18
C12: =Setup!B11 -> 7 | D12: =C22 -> 5 | E12: =C28 -> 10 | F12: =C4 -> 6 | G12: =C10 -> 6
C13: =Setup!B12 -> Keith | D13: =C13 -> Keith | E13: =C21 -> Dave | F13: =C23 -> Hunter | G13: =F13 -> Hunter
C14: =Setup!B13 -> 16 | D14: =C14 -> 16 | E14: =C22 -> 5 | F14: =C24 -> 7 | G14: =F14 -> 7
C15: =Setup!B14 -> Tony W | D15: =C5 -> John | E15: =C7 -> Brian P | F15: =C29 -> Patrick | G15: =C27 -> Bob | J15: Player | K15: 9-Hole HC | L15: Stroke Play HC | M15: Par 3
C16: =Setup!B15 -> 10 | D16: =C6 -> 7 | E16: =C8 -> 6 | F16: =C30 -> 8 | G16: =C28 -> 10
C17: =Setup!B16 -> Manny | D17: =C29 -> Patrick | E17: =C17 -> Manny | F17: =C17 -> Manny | G17: =C13 -> Keith | J17: =Setup!B2 -> Mil | K17: =ROUND(Setup!H2,0) -> 6 | L17: =ROUND(Setup!I2,0) -> 12 | M17: =ROUND(Setup!J2,0) -> 4
C18: =Setup!B17 -> 14 | D18: =C30 -> 8 | E18: =C18 -> 14 | F18: =C18 -> 14 | G18: =C14 -> 16 | L18: =Setup!I3 -> 0
A19: GROUP 3 | C19: =Setup!B18 -> Tommy | D19: =C7 -> Brian P | E19: =C9 -> Pat | F19: =C13 -> Keith | G19: =C5 -> John | J19: =Setup!B4 -> John | K19: =ROUND(Setup!H4,0) -> 7 | L19: =ROUND(Setup!I4,0) -> 14 | M19: =ROUND(Setup!J4,0) -> 5
C20: =Setup!B19 -> 5 | D20: =C8 -> 6 | E20: =C10 -> 6 | F20: =C14 -> 16 | G20: =C6 -> 7 | K20: =Setup!H5 -> 0 | L20: =Setup!I5 -> 0 | M20: =Setup!J5 -> 0
C21: =Setup!B20 -> Dave | D21: =C23 -> Hunter | E21: =C15 -> Tony W | F21: =C33 -> Chris | G21: =C17 -> Manny | J21: =Setup!B6 -> Brian P | K21: =ROUND(Setup!H6,0) -> 6 | L21: =ROUND(Setup!I6,0) -> 12 | M21: =ROUND(Setup!J6,0) -> 4
C22: =Setup!B21 -> 5 | D22: =C24 -> 7 | E22: =C16 -> 10 | F22: =C34 -> 15 | G22: =C18 -> 14 | K22: =Setup!H7 -> 0 | L22: =Setup!I7 -> 0 | M22: =Setup!J7 -> 0
C23: =Setup!B22 -> Hunter | D23: =C31 -> Brian S | E23: =C19 -> Tommy | F23: =C7 -> Brian P | G23: =C31 -> Brian S | J23: =Setup!B8 -> Pat | K23: =ROUND(Setup!H8,0) -> 6 | L23: =ROUND(Setup!I8,0) -> 13 | M23: =ROUND(Setup!J8,0) -> 5
C24: =Setup!B23 -> 7 | D24: =C32 -> 13 | E24: =C20 -> 5 | F24: =C8 -> 6 | G24: =C32 -> 13 | K24: =Setup!H9 -> 0 | L24: =Setup!I9 -> 0 | M24: =Setup!J9 -> 0
C25: =Setup!B24 -> Gerald C | D25: =C15 -> Tony W | E25: =C29 -> Patrick | F25: =C19 -> Tommy | G25: =F25 -> Tommy | J25: =Setup!B10 -> Rick | K25: =ROUND(Setup!H10,0) -> 7 | L25: =ROUND(Setup!I10,0) -> 15 | M25: =ROUND(Setup!J10,0) -> 6
C26: =Setup!B25 -> 12 | D26: =C16 -> 10 | E26: =C30 -> 8 | F26: =C20 -> 5 | G26: =F26 -> 5 | K26: =Setup!H11 -> 0 | L26: =Setup!I11 -> 0 | M26: =Setup!J11 -> 0
A27: GROUP 4 | C27: =Setup!B26 -> Bob | D27: =C9 -> Pat | E27: =C3 -> Mil | F27: =C25 -> Gerald C | G27: =C3 -> Mil | J27: =Setup!B12 -> Keith | K27: =ROUND(Setup!H12,0) -> 16 | L27: =ROUND(Setup!I12,0) -> 32 | M27: =ROUND(Setup!J12,0) -> 12
C28: =Setup!B27 -> 10 | D28: =C10 -> 6 | E28: =C4 -> 6 | F28: =C26 -> 12 | G28: =C4 -> 6 | K28: =Setup!H13 -> 0 | L28: =Setup!I13 -> 0 | M28: =Setup!J13 -> 0
C29: =Setup!B28 -> Patrick | D29: =C33 -> Chris | E29: =C31 -> Brian S | F29: =C5 -> John | G29: =C21 -> Dave | J29: =Setup!B14 -> Tony W | K29: =ROUND(Setup!H14,0) -> 10 | L29: =ROUND(Setup!I14,0) -> 19 | M29: =ROUND(Setup!J14,0) -> 7
C30: =Setup!B29 -> 8 | D30: =C34 -> 15 | E30: =C32 -> 13 | F30: =C6 -> 7 | G30: =C22 -> 5 | K30: =Setup!H15 -> 0 | L30: =Setup!I15 -> 0 | M30: =Setup!J15 -> 0
C31: =Setup!B30 -> Brian S | D31: =C25 -> Gerald C | E31: =C13 -> Keith | F31: =C15 -> Tony W | G31: =F31 -> Tony W | J31: =Setup!B16 -> Manny | K31: =ROUND(Setup!H16,0) -> 14 | L31: =ROUND(Setup!I16,0) -> 28 | M31: =ROUND(Setup!J16,0) -> 10
C32: =Setup!B31 -> 13 | D32: =C26 -> 12 | E32: =C14 -> 16 | F32: =C16 -> 10 | G32: =F32 -> 10
C33: =Setup!B32 -> Chris | D33: =C17 -> Manny | E33: =C25 -> Gerald C | F33: =C27 -> Bob | G33: =C33 -> Chris | J33: =Setup!B18 -> Tommy | K33: =ROUND(Setup!H18,0) -> 5 | L33: =ROUND(Setup!I18,0) -> 10 | M33: =ROUND(Setup!J18,0) -> 4
C34: =Setup!B33 -> 15 | D34: =C18 -> 14 | E34: =C26 -> 12 | F34: =C28 -> 10 | G34: =C34 -> 15
J35: =Setup!B20 -> Dave | K35: =ROUND(Setup!H20,0) -> 5 | L35: =ROUND(Setup!I20,0) -> 10 | M35: =ROUND(Setup!J20,0) -> 4
J37: =Setup!B22 -> Hunter | K37: =ROUND(Setup!H22,0) -> 7 | L37: =ROUND(Setup!I22,0) -> 15 | M37: =ROUND(Setup!J22,0) -> 6
J39: =Setup!B24 -> Gerald C | K39: =ROUND(Setup!H24,0) -> 12 | L39: =ROUND(Setup!I24,0) -> 24 | M39: =ROUND(Setup!J24,0) -> 9
J41: =Setup!B26 -> Bob | K41: =ROUND(Setup!H26,0) -> 10 | L41: =ROUND(Setup!I26,0) -> 20 | M41: =ROUND(Setup!J26,0) -> 7
J43: =Setup!B28 -> Patrick | K43: =ROUND(Setup!H28,0) -> 8 | L43: =ROUND(Setup!I28,0) -> 15 | M43: =ROUND(Setup!J28,0) -> 6
C44: Course | D44: Tees | E44: Yardage | F44: Par | J44: =Setup!B30 -> Brian S | K44: =ROUND(Setup!H30,0) -> 13 | L44: =ROUND(Setup!I30,0) -> 26 | M44: =ROUND(Setup!J30,0) -> 10
...

Sheet Scores
A1: Player | B1: =Courses!A5 -> Eagle Mountain | C1: =Courses!A15 -> Wekopa Cholla | D1: =Courses!A25 -> Wekopa Saguaro | E1: =Courses!A35 -> Kierland A/M | F1: =Courses!A56 -> Troon N MNMT | G1: Tie Breaker | J1: AVG Score | K1: HCP | L1: Net Score | M1: Rank
A2: ='Day 1 - Match 1'!M6 -> Mil | B2: =SUM('Day 1 - Match 1:Day 1 - Match 2'!N6) -> 87 | C2: =SUM('Day 2A - Match 4:Day 2A - Match 5'!N6) -> 93 | D2: =SUM('Day 2B - Match 7:Day 2B - Match 8'!N6) -> 98 | E2: =SUM('Day 3 - Match 10:Day 3 - Match 11'!N6) -> 91 | F2: =SUM('Day 4 - Front 9:Day 4 - Back 9'!N6) -> 101 | G2: =_xlfn.IFS(M2=1,"Winner",M2=2,"2nd",M2=3,"3rd",TRUE,"") | J2: =AVERAGE(B2:F2) -> 94 | K2: =Setup!I2 -> 11.885841 | L2: =J2-K2 -> 82.114159 | M2: =RANK(L2,L$2:L$33,1) -> 9
A4: ='Day 1 - Match 1'!M8 -> John | B4: =SUM('Day 1 - Match 1:Day 1 - Match 2'!N8) -> 83 | C4: =SUM('Day 2A - Match 4:Day 2A - Match 5'!N8) -> 91 | D4: =SUM('Day 2B - Match 7:Day 2B - Match 8'!N8) -> 101 | E4: =SUM('Day 3 - Match 10:Day 3 - Match 11'!N8) -> 88 | F4: =SUM('Day 4 - Front 9:Day 4 - Back 9'!N8) -> 83 | G4: =_xlfn.IFS(M4=1,"Winner",M4=2,"2nd",M4=3,"3rd",TRUE,"") -> 3rd | J4: =AVERAGE(B4:F4) -> 89.2 | K4: =Setup!I4 -> 13.893451 | L4: =J4-K4 -> 75.306549 | M4: =RANK(L4,L$2:L$33,1) -> 3
A6: ='Day 1 - Match 1'!M10 -> Brian P | B6: =SUM('Day 1 - Match 1:Day 1 - Match 2'!N10) -> 94 | C6: =SUM('Day 2A - Match 4:Day 2A - Match 5'!N10) -> 96 | D6: =SUM('Day 2B - Match 7:Day 2B - Match 8'!N10) -> 100 | E6: =SUM('Day 3 - Match 10:Day 3 - Match 11'!N10) -> 89 | F6: =SUM('Day 4 - Front 9:Day 4 - Back 9'!N10) -> 88 | G6: =_xlfn.IFS(M6=1,"Winner",M6=2,"2nd",M6=3,"3rd",TRUE,"") | J6: =AVERAGE(B6:F6) -> 93.4 | K6: =Setup!I6 -> 11.908673 | L6: =J6-K6 -> 81.491327 | M6: =RANK(L6,L$2:L$33,1) -> 8
A8: ='Day 1 - Match 1'!M12 -> Pat | B8: =SUM('Day 1 - Match 1:Day 1 - Match 2'!N12) -> 89 | C8: =SUM('Day 2A - Match 4:Day 2A - Match 5'!N12) -> 91 | D8: =SUM('Day 2B - Match 7:Day 2B - Match 8'!N12) -> 88 | E8: =SUM('Day 3 - Match 10:Day 3 - Match 11'!N12) -> 91 | F8: =SUM('Day 4 - Front 9:Day 4 - Back 9'!N12) -> 90 | G8: =_xlfn.IFS(M8=1,"Winner",M8=2,"2nd",M8=3,"3rd",TRUE,"") | J8: =AVERAGE(B8:F8) -> 89.8 | K8: =Setup!I8 -> 12.901062 | L8: =J8-K8 -> 76.898938 | M8: =RANK(L8,L$2:L$33,1) -> 4
A10: ='Day 1 - Match 1'!M14 -> Rick | B10: =SUM('Day 1 - Match 1:Day 1 - Match 2'!N14) -> 91 | C10: =SUM('Day 2A - Match 4:Day 2A - Match 5'!N14) -> 84 | D10: =SUM('Day 2B - Match 7:Day 2B - Match 8'!N14) -> 95 | E10: =SUM('Day 3 - Match 10:Day 3 - Match 11'!N14) -> 84 | F10: =SUM('Day 4 - Front 9:Day 4 - Back 9'!N14) -> 94 | G10: =_xlfn.IFS(M10=1,"Winner",M10=2,"2nd",M10=3,"3rd",TRUE,"") -> 2nd | J10: =AVERAGE(B10:F10) -> 89.6 | K10: =Setup!I10 -> 14.885841 | L10: =J10-K10 -> 74.714159 | M10: =RANK(L10,L$2:L$33,1) -> 2
A12: ='Day 1 - Match 1'!M16 -> Keith | B12: =SUM('Day 1 - Match 1:Day 1 - Match 2'!N16) -> 106 | C12: =SUM('Day 2A - Match 4:Day 2A - Match 5'!N16) -> 119 | D12: =SUM('Day 2B - Match 7:Day 2B - Match 8'!N16) -> 121 | E12: =SUM('Day 3 - Match 10:Day 3 - Match 11'!N16) -> 102 | F12: =SUM('Day 4 - Front 9:Day 4 - Back 9'!N16) -> 131 | G12: =_xlfn.IFS(M12=1,"Winner",M12=2,"2nd",M12=3,"3rd",TRUE,"") | J12: =AVERAGE(B12:F12) -> 115.8 | K12: =Setup!I12 -> 32 | L12: =J12-K12 -> 83.8 | M12: =RANK(L12,L$2:L$33,1) -> 11
A14: ='Day 1 - Match 1'!M18 -> Tony W | B14: =SUM('Day 1 - Match 1:Day 1 - Match 2'!N18) -> 100 | C14: =SUM('Day 2A - Match 4:Day 2A - Match 5'!N18) -> 108 | D14: =SUM('Day 2B - Match 7:Day 2B - Match 8'!N18) -> 110 | E14: =SUM('Day 3 - Match 10:Day 3 - Match 11'!N18) -> 109 | F14: =SUM('Day 4 - Front 9:Day 4 - Back 9'!N18) -> 107 | G14: =_xlfn.IFS(M14=1,"Winner",M14=2,"2nd",M14=3,"3rd",TRUE,"") | J14: =AVERAGE(B14:F14) -> 106.8 | K14: =Setup!I14 -> 19.494938 | L14: =J14-K14 -> 87.305062 | M14: =RANK(L14,L$2:L$33,1) -> 15
A16: ='Day 1 - Match 1'!M20 -> Manny | B16: =SUM('Day 1 - Match 1:Day 1 - Match 2'!N20) -> 118 | C16: =SUM('Day 2A - Match 4:Day 2A - Match 5'!N20) -> 108 | D16: =SUM('Day 2B - Match 7:Day 2B - Match 8'!N20) -> 126 | E16: =SUM('Day 3 - Match 10:Day 3 - Match 11'!N20) -> 114 | F16: =SUM('Day 4 - Front 9:Day 4 - Back 9'!N20) -> 113 | G16: =_xlfn.IFS(M16=1,"Winner",M16=2,"2nd",M16=3,"3rd",TRUE,"") | J16: =AVERAGE(B16:F16) -> 115.8 | K16: =Setup!I16 -> 27.786903 | L16: =J16-K16 -> 88.013097 | M16: =RANK(L16,L$2:L$33,1) -> 16
A18: ='Day 1 - Match 1'!M22 -> Tommy | B18: =SUM('Day 1 - Match 1:Day 1 - Match 2'!N22) -> 88 | C18: =SUM('Day 2A - Match 4:Day 2A - Match 5'!N22) -> 80 | D18: =SUM('Day 2B - Match 7:Day 2B - Match 8'!N22) -> 79 | E18: =SUM('Day 3 - Match 10:Day 3 - Match 11'!N22) -> 86 | F18: =SUM('Day 4 - Front 9:Day 4 - Back 9'!N22) -> 87 | G18: =_xlfn.IFS(M18=1,"Winner",M18=2,"2nd",M18=3,"3rd",TRUE,"") -> Winner | J18: =AVERAGE(B18:F18) -> 84 | K18: =Setup!I18 -> 10.364956 | L18: =J18-K18 -> 73.635044 | M18: =RANK(L18,L$2:L$33,1) -> 1
A20: ='Day 1 - Match 1'!M24 -> Dave | B20: =SUM('Day 1 - Match 1:Day 1 - Match 2'!N24) -> 88 | C20: =SUM('Day 2A - Match 4:Day 2A - Match 5'!N24) -> 85 | D20: =SUM('Day 2B - Match 7:Day 2B - Match 8'!N24) -> 89 | E20: =SUM('Day 3 - Match 10:Day 3 - Match 11'!N24) -> 90 | F20: =SUM('Day 4 - Front 9:Day 4 - Back 9'!N24) -> 88 | G20: =_xlfn.IFS(M20=1,"Winner",M20=2,"2nd",M20=3,"3rd",TRUE,"") | J20: =AVERAGE(B20:F20) -> 88 | K20: =Setup!I20 -> 9.7033628 | L20: =J20-K20 -> 78.296637 | M20: =RANK(L20,L$2:L$33,1) -> 6
A22: ='Day 1 - Match 1'!M26 -> Hunter | B22: =SUM('Day 1 - Match 1:Day 1 - Match 2'!N26) -> 104 | C22: =SUM('Day 2A - Match 4:Day 2A - Match 5'!N26) -> 93 | D22: =SUM('Day 2B - Match 7:Day 2B - Match 8'!N26) -> 96 | E22: =SUM('Day 3 - Match 10:Day 3 - Match 11'!N26) -> 88 | F22: =SUM('Day 4 - Front 9:Day 4 - Back 9'!N26) -> 120 | G22: =_xlfn.IFS(M22=1,"Winner",M22=2,"2nd",M22=3,"3rd",TRUE,"") | J22: =AVERAGE(B22:F22) -> 100.2 | K22: =Setup!I22 -> 14.775575 | L22: =J22-K22 -> 85.424425 | M22: =RANK(L22,L$2:L$33,1) -> 12
A24: ='Day 1 - Match 1'!M28 -> Gerald C | B24: =SUM('Day 1 - Match 1:Day 1 - Match 2'!N28) -> 112 | C24: =SUM('Day 2A - Match 4:Day 2A - Match 5'!N28) -> 112 | D24: =SUM('Day 2B - Match 7:Day 2B - Match 8'!N28) -> 114 | E24: =SUM('Day 3 - Match 10:Day 3 - Match 11'!N28) -> 107 | F24: =SUM('Day 4 - Front 9:Day 4 - Back 9'!N28) -> 112 | G24: =_xlfn.IFS(M24=1,"Winner",M24=2,"2nd",M24=3,"3rd",TRUE,"") | J24: =AVERAGE(B24:F24) -> 111.4 | K24: =Setup!I24 -> 24.346619 | L24: =J24-K24 -> 87.053381 | M24: =RANK(L24,L$2:L$33,1) -> 13
... A32: ='Day 1 - Match 1'!M36 -> Chris | B32: =SUM('Day 1 - Match 1:Day 1 - Match 2'!N36) -> 113 | C32: =SUM('Day 2A - Match 4:Day 2A - Match 5'!N36) -> 103 | D32: =SUM('Day 2B - Match 7:Day 2B - Match 8'!N36) -> 117 | E32: =SUM('Day 3 - Match 10:Day 3 - Match 11'!N36) -> 107 | F32: =SUM('Day 4 - Front 9:Day 4 - Back 9'!N36) -> 122 | G32: =_xlfn.IFS(M32=1,"Winner",M32=2,"2nd",M32=3,"3rd",TRUE,"") | J32: =AVERAGE(B32:F32) -> 112.4 | K32: =Setup!I32 -> 29.881947 | L32: =J32-K32 -> 82.518053 | M32: =RANK(L32,L$2:L$33,1) -> 10

Sheet Points
A1: Player | B1: Day 1 - Points | C1: Day 2 - Points | D1: Day 3 -Points | E1: Day 4 -Points | F1: Day 1 Match 1 | G1: Day 1 Match 2 | H1: Day 1 Match 3 | I1: Day 1 Stroke Play | J1: Day 2A Match 4 | K1: Day 2A Match 5 | L1: Day 2A Match 6 | M1: Day 2B Match 7 | N1: Day 2B Match 8 | O1: Day 2B Match 9 | P1: Day 3 Match 10 | Q1: Day 3 Match 11 | R1: Day 3 Match 12 | S1: Day 3 Stroke Play | T1: Day 3 Scramble | AE1: 1 | AF1: 2 | AG1: 3 | AH1: 4 | AI1: 5 | AJ1: 6 | AK1: 7 | AL1: 8 | AM1: 9 | AN1: 10 | AQ1: 1st Place | AY1: Winner | AZ1: 2nd Place | BA1: 3rd Place | BB1: 4th Place | BG1: Day 1 & 2 | BH1: Day 1-3
A2: =Setup!B2 -> Mil | B2: =SUM(F2:I2) -> 4 | C2: =SUM(J2:O2) -> 6 | D2: =SUM(P2:T2) -> 5 | E2: =N38 -> 0 | F2: ='Day 1 - Match 1'!O6 -> 1 | G2: ='Day 1 - Match 2'!O6 -> 0 | H2: ='Day 1 - Match 3'!O6 -> 1 | I2: =F38 -> 2 | J2: ='Day 2A - Match 4'!O6 -> 0 | K2: ='Day 2A - Match 5'!O6 -> 0 | L2: ='Day 2A - Match 6'!O6 -> 0 | M2: ='Day 2B - Match 7'!O6 -> 2 | N2: ='Day 2B - Match 8'!O6 -> 2 | O2: ='Day 2B - Match 9'!O6 -> 2 | P2: ='Day 3 - Match 10'!O6 -> 1 | Q2: ='Day 3 - Match 11'!O6 -> 2 | R2: ='Day 3 - Match 12'!O6 -> 2 | S2: =J38 -> 0 | T2: =Scramble!AG6 -> 0 | U2: =A2 -> Mil | AB2: 1 | AC2: =COUNTIF($M$38:$M$53,AB2) -> 1 | AD2: =Setup!C49 -> 12 | AE2: =IF($AC2=AE$1,$AD2,0) -> 12 | AF2: =IF($AC2=$AF$1,SUM($AD2:$AD4)/$AF$1,0) -> 0 | AG2: =IF($AC2=$AG$1,SUM($AD2:$AD6)/$AG$1,0) -> 0 | AH2: =IF($AC2=$AH$1,SUM($AD2:$AD8)/$AH$1,0) -> 0 | AI2: =IF($AC2=AI$1,SUM($AD2:$AD10)/AI$1,0) -> 0 | AJ2: =IF($AC2=AJ$1,SUM($AD2:$AD12)/AJ$1,0) -> 0 | AK2: =IF($AC2=AK$1,SUM($AD2:$AD14)/AK$1,0) -> 0 | AO2: =COUNTIF(Results!R$5:R$36,AB2) -> 1 | AQ2: =IF($AC2=AE$1,Setup!$C$42,0) -> 700 | AU2: =IF(Results!$R5=$AB$2,Results!AV5,"") | AV2: =IF(Results!$R5=$AB$4,Results!AW5,"") | AW2: =IF(Results!$R5=$AB$6,Results!AX5,"") | AX2: =IF(Results!$R5=$AB$8,Results!AY5,"") | AY2: =IF(Results!R5=AB$2,"Winner","") | AZ2: =IF(Results!R5=AB$4,"2nd Place","") | BA2: =IF(Results!R5=AB$6,"3rd Place","") | BB2: =IF(Results!R5=AB$8,"4th Place","") | BD2: =IF(ISNUMBER(FIND("Winner",Results!J5)),Setup!C$42,IF(ISNUMBER(FIND("2nd Place",Results!J5)),Setup!C$43,IF(ISNUMBER(FIND("3rd Place",Results!J5)),Setup!C$44,""))) | BG2: =SUM(F2:O2) -> 10 | BH2: =SUM(P2:T2)+BG2 -> 15
A4: =Setup!B4 -> John | B4: =SUM(F4:I4) -> 7 | C4: =SUM(J4:O4) -> 7 | D4: =SUM(P4:T4) -> 9 | E4: =N39 -> 12 | F4: ='Day 1 - Match 1'!O8 -> 1 | G4: ='Day 1 - Match 2'!O8 -> 2 | H4: ='Day 1 - Match 3'!O8 -> 2 | I4: =F39 -> 2 | J4: ='Day 2A - Match 4'!O8 -> 2 | K4: ='Day 2A - Match 5'!O8 -> 1 | L4: ='Day 2A - Match 6'!O8 -> 2 | M4: ='Day 2B - Match 7'!O8 -> 2 | N4: ='Day 2B - Match 8'!O8 -> 0 | O4: ='Day 2B - Match 9'!O8 -> 0 | P4: ='Day 3 - Match 10'!O8 -> 2 | Q4: ='Day 3 - Match 11'!O8 -> 2 | R4: ='Day 3 - Match 12'!O8 -> 2 | S4: =J39 -> 2 | T4: =Scramble!AG8 -> 1 | U4: =A4 -> John | AB4: 2 | AC4: =COUNTIF($M$38:$M$53,AB4) -> 1 | AD4: =Setup!C50 -> 10 | AE4: =IF($AC4=AE$1,$AD4,0) -> 10 | AF4: =IF($AC4=$AF$1,SUM($AD4:$AD6)/$AF$1,0) -> 0 | AG4: =IF($AC4=$AG$1,SUM($AD4:$AD8)/$AG$1,0) -> 0 | AH4: =IF($AC4=$AH$1,SUM($AD4:$AD10)/$AH$1,0) -> 0 | AI4: =IF($AC4=AI$1,SUM($AD4:$AD12)/AI$1,0) -> 0 | AJ4: =IF($AC4=AJ$1,SUM($AD4:$AD14)/AJ$1,0) -> 0 | AK4: =IF($AC4=AK$1,SUM($AD4:$AD16)/AK$1,0) -> 0 | AO4: =COUNTIF(Results!R$5:R$36,AB4) -> 1 | AU4: =IF(Results!$R7=$AB$2,Results!AV7,"") -> 700 | AV4: =IF(Results!$R7=$AB$4,Results!AW7,"") | AW4: =IF(Results!$R7=$AB$6,Results!AX7,"") | AX4: =IF(Results!$R7=$AB$8,Results!AY7,"") | AY4: =IF(Results!R7=AB$2,"Winner","") -> Winner | AZ4: =IF(Results!R7=AB$4,"2nd Place","") | BA4: =IF(Results!R7=AB$6,"3rd Place","") | BB4: =IF(Results!R7=AB$8,"4th Place","") | BD4: =IF(ISNUMBER(FIND("Winner",Results!J7)),Setup!C$42,IF(ISNUMBER(FIND("2nd Place",Results!J7)),Setup!C$43,IF(ISNUMBER(FIND("3rd Place",Results!J7)),Setup!C$44,""))) -> 700 | BG4: =SUM(F4:O4) -> 14 | BH4: =SUM(P4:T4)+BG4 -> 23
U5: =A5 -> 0 | BG5: =SUM(F5:O5) -> 0 | BH5: =SUM(P5:T5)+BG5 -> 0
A6: =Setup!B6 -> Brian P | B6: =SUM(F6:I6) -> 2 | C6: =SUM(J6:O6) -> 10 | D6: =SUM(P6:T6) -> 9 | E6: =N40 -> 8.5 | F6: ='Day 1 - Match 1'!O10 -> 0 | G6: ='Day 1 - Match 2'!O10 -> 2 | H6: ='Day 1 - Match 3'!O10 -> 0 | I6: =F40 -> 0 | J6: ='Day 2A - Match 4'!O10 -> 2 | K6: ='Day 2A - Match 5'!O10 -> 2 | L6: ='Day 2A - Match 6'!O10 -> 2 | M6: ='Day 2B - Match 7'!O10 -> 0 | N6: ='Day 2B - Match 8'!O10 -> 2 | O6: ='Day 2B - Match 9'!O10 -> 2 | P6: ='Day 3 - Match 10'!O10 -> 0 | Q6: ='Day 3 - Match 11'!O10 -> 2 | R6: ='Day 3 - Match 12'!O10 -> 2 | S6: =J40 -> 2 | T6: =Scramble!AG10 -> 3 | U6: =A6 -> Brian P | AB6: 3 | AC6: =COUNTIF($M$38:$M$53,AB6) -> 1 | AD6: =Setup!C51 -> 8.5 | AE6: =IF($AC6=AE$1,$AD6,0) -> 8.5 | AF6: =IF($AC6=$AF$1,SUM($AD6:$AD8)/$AF$1,0) -> 0 | AG6: =IF($AC6=$AG$1,SUM($AD6:$AD10)/$AG$1,0) -> 0 | AH6: =IF($AC6=$AH$1,SUM($AD6:$AD12)/$AH$1,0) -> 0 | AI6: =IF($AC6=AI$1,SUM($AD6:$AD14)/AI$1,0) -> 0 | AJ6: =IF($AC6=AJ$1,SUM($AD6:$AD16)/AJ$1,0) -> 0 | AK6: =IF($AC6=AK$1,SUM($AD6:$AD18)/AK$1,0) -> 0 | AO6: =COUNTIF(Results!R$5:R$36,AB6) -> 1 | AU6: =IF(Results!$R9=$AB$2,Results!AV9,"") | AV6: =IF(Results!$R9=$AB$4,Results!AW9,"") | AW6: =IF(Results!$R9=$AB$6,Results!AX9,"") -> 150 | AX6: =IF(Results!$R9=$AB$8,Results!AY9,"") | AY6: =IF(Results!R9=AB$2,"Winner","") | AZ6: =IF(Results!R9=AB$4,"2nd Place","") | BA6: =IF(Results!R9=AB$6,"3rd Place","") -> 3rd Place | BB6: =IF(Results!R9=AB$8,"4th Place","") | BD6: =IF(ISNUMBER(FIND("Winner",Results!J9)),Setup!C$42,IF(ISNUMBER(FIND("2nd Place",Results!J9)),Setup!C$43,IF(ISNUMBER(FIND("3rd Place",Results!J9)),Setup!C$44,""))) -> 150 | BG6: =SUM(F6:O6) -> 12 | BH6: =SUM(P6:T6)+BG6 -> 21
U7: =A7 -> 0 | BG7: =SUM(F7:O7) -> 0 | BH7: =SUM(P7:T7)+BG7 -> 0
A8: =Setup!B8 -> Pat | B8: =SUM(F8:I8) -> 5 | C8: =SUM(J8:O8) -> 7 | D8: =SUM(P8:T8) -> 5 | E8: =N41 -> 6.625 | F8: ='Day 1 - Match 1'!O12 -> 2 | G8: ='Day 1 - Match 2'!O12 -> 0 | H8: ='Day 1 - Match 3'!O12 -> 1 | I8: =F41 -> 2 | J8: ='Day 2A - Match 4'!O12 -> 2 | K8: ='Day 2A - Match 5'!O12 -> 0 | L8: ='Day 2A - Match 6'!O12 -> 1 | M8: ='Day 2B - Match 7'!O12 -> 2 | N8: ='Day 2B - Match 8'!O12 -> 0 | O8: ='Day 2B - Match 9'!O12 -> 2 | P8: ='Day 3 - Match 10'!O12 -> 0 | Q8: ='Day 3 - Match 11'!O12 -> 0 | R8: ='Day 3 - Match 12'!O12 -> 1 | S8: =J41 -> 2 | T8: =Scramble!AG12 -> 2 | U8: =A8 -> Pat | AB8: 4 | AC8: =COUNTIF($M$38:$M$53,AB8) -> 2 | AD8: =Setup!C52 -> 7.25 | AE8: =IF($AC8=AE$1,$AD8,0) -> 0 | AF8: =IF($AC8=$AF$1,SUM($AD8:$AD10)/$AF$1,0) -> 6.625 | AG8: =IF($AC8=$AG$1,SUM($AD8:$AD12)/$AG$1,0) -> 0 | AH8: =IF($AC8=$AH$1,SUM($AD8:$AD14)/$AH$1,0) -> 0 | AI8: =IF($AC8=AI$1,SUM($AD8:$AD16)/AI$1,0) -> 0 | AJ8: =IF($AC8=AJ$1,SUM($AD8:$AD18)/AJ$1,0) -> 0 | AK8: =IF($AC8=AK$1,SUM($AD8:$AD20)/AK$1,0) -> 0 | AO8: =COUNTIF(Results!R$5:R$36,AB8) -> 1 | AU8: =IF(Results!$R11=$AB$2,Results!AV11,"") | AV8: =IF(Results!$R11=$AB$4,Results!AW11,"") | AW8: =IF(Results!$R11=$AB$6,Results!AX11,"") | AX8: =IF(Results!$R11=$AB$8,Results!AY11,"") | AY8: =IF(Results!R11=AB$2,"Winner","") | AZ8: =IF(Results!R11=AB$4,"2nd Place","") | BA8: =IF(Results!R11=AB$6,"3rd Place","") | BB8: =IF(Results!R11=AB$8,"4th Place","") | BD8: =IF(ISNUMBER(FIND("Winner",Results!J11)),Setup!C$42,IF(ISNUMBER(FIND("2nd Place",Results!J11)),Setup!C$43,IF(ISNUMBER(FIND("3rd Place",Results!J11)),Setup!C$44,""))) | BG8: =SUM(F8:O8) -> 12 | BH8: =SUM(P8:T8)+BG8 -> 17
U9: =A9 -> 0 | BG9: =SUM(F9:O9) -> 0 | BH9: =SUM(P9:T9)+BG9 -> 0
A10: =Setup!B10 -> Rick | B10: =SUM(F10:I10) -> 6 | C10: =SUM(J10:O10) -> 6 | D10: =SUM(P10:T10) -> 9 | E10: =N42 -> 4 | F10: ='Day 1 - Match 1'!O14 -> 0 | G10: ='Day 1 - Match 2'!O14 -> 2 | H10: ='Day 1 - Match 3'!O14 -> 2 | I10: =F42 -> 2 | J10: ='Day 2A - Match 4'!O14 -> 2 | K10: ='Day 2A - Match 5'!O14 -> 1 | L10: ='Day 2A - Match 6'!O14 -> 0 | M10: ='Day 2B - Match 7'!O14 -> 0 | N10: ='Day 2B - Match 8'!O14 -> 2 | O10: ='Day 2B - Match 9'!O14 -> 1 | P10: ='Day 3 - Match 10'!O14 -> 2 | Q10: ='Day 3 - Match 11'!O14 -> 2 | R10: ='Day 3 - Match 12'!O14 -> 0 | S10: =J42 -> 2 | T10: =Scramble!AG14 -> 3 | U10: =A10 -> Rick | AB10: 5 | AC10: =COUNTIF($M$38:$M$53,AB10) -> 0 | AD10: =Setup!C53 -> 6 | AE10: =IF($AC10=AE$1,$AD10,0) -> 0 | AF10: =IF($AC10=$AF$1,SUM($AD10:$AD12)/$AF$1,0) -> 0 | AG10: =IF($AC10=$AG$1,SUM($AD10:$AD14)/$AG$1,0) -> 0 | AH10: =IF($AC10=$AH$1,SUM($AD10:$AD16)/$AH$1,0) -> 0 | AI10: =IF($AC10=AI$1,SUM($AD10:$AD18)/AI$1,0) -> 0 | AJ10: =IF($AC10=AJ$1,SUM($AD10:$AD20)/AJ$1,0) -> 0 | AK10: =IF($AC10=AK$1,SUM($AD10:$AD22)/AK$1,0) -> 0 | AO10: =COUNTIF(Results!R$5:R$36,AB10) -> 1 | AU10: =IF(Results!$R13=$AB$2,Results!AV13,"") | AV10: =IF(Results!$R13=$AB$4,Results!AW13,"") | AW10: =IF(Results!$R13=$AB$6,Results!AX13,"") | AX10: =IF(Results!$R13=$AB$8,Results!AY13,"") | AY10: =IF(Results!R13=AB$2,"Winner","") | AZ10: =IF(Results!R13=AB$4,"2nd Place","") | BA10: =IF(Results!R13=AB$6,"3rd Place","") | BB10: =IF(Results!R13=AB$8,"4th Place","") | BD10: =IF(ISNUMBER(FIND("Winner",Results!J13)),Setup!C$42,IF(ISNUMBER(FIND("2nd Place",Results!J13)),Setup!C$43,IF(ISNUMBER(FIND("3rd Place",Results!J13)),Setup!C$44,""))) | BG10: =SUM(F10:O10) -> 12 | BH10: =SUM(P10:T10)+BG10 -> 21
U11: =A11 -> 0 | BG11: =SUM(F11:O11) -> 0 | BH11: =SUM(P11:T11)+BG11 -> 0
A12: =Setup!B12 -> Keith | B12: =SUM(F12:I12) -> 8 | C12: =SUM(J12:O12) -> 2 | D12: =SUM(P12:T12) -> 6 | E12: =N43 -> 0 | F12: ='Day 1 - Match 1'!O16 -> 2 | G12: ='Day 1 - Match 2'!O16 -> 2 | H12: ='Day 1 - Match 3'!O16 -> 2 | I12: =F43 -> 2 | J12: ='Day 2A - Match 4'!O16 -> 0 | K12: ='Day 2A - Match 5'!O16 -> 0 | L12: ='Day 2A - Match 6'!O16 -> 0 | M12: ='Day 2B - Match 7'!O16 -> 2 | N12: ='Day 2B - Match 8'!O16 -> 0 | O12: ='Day 2B - Match 9'!O16 -> 0 | P12: ='Day 3 - Match 10'!O16 -> 2 | Q12: ='Day 3 - Match 11'!O16 -> 0 | R12: ='Day 3 - Match 12'!O16 -> 0 | S12: =J43 -> 2 | T12: =Scramble!AG16 -> 2 | U12: =A12 -> Keith | AB12: 6 | AC12: =COUNTIF($M$38:$M$53,AB12) -> 1 | AD12: =Setup!C54 -> 5 | AE12: =IF($AC12=AE$1,$AD12,0) -> 5 | AF12: =IF($AC12=$AF$1,SUM($AD12:$AD14)/$AF$1,0) -> 0 | AG12: =IF($AC12=$AG$1,SUM($AD12:$AD16)/$AG$1,0) -> 0 | AH12: =IF($AC12=$AH$1,SUM($AD12:$AD18)/$AH$1,0) -> 0 | AI12: =IF($AC12=AI$1,SUM($AD12:$AD20)/AI$1,0) -> 0 | AJ12: =IF($AC12=AJ$1,SUM($AD12:$AD22)/AJ$1,0) -> 0 | AK12: =IF($AC12=AK$1,SUM($AD12:$AD24)/AK$1,0) -> 0 | AO12: =COUNTIF(Results!R$5:R$36,AB12) -> 1 | AU12: =IF(Results!$R15=$AB$2,Results!AV15,"") | AV12: =IF(Results!$R15=$AB$4,Results!AW15,"") | AW12: =IF(Results!$R15=$AB$6,Results!AX15,"") | AX12: =IF(Results!$R15=$AB$8,Results!AY15,"") | AY12: =IF(Results!R15=AB$2,"Winner","") | AZ12: =IF(Results!R15=AB$4,"2nd Place","") | BA12: =IF(Results!R15=AB$6,"3rd Place","") | BB12: =IF(Results!R15=AB$8,"4th Place","") | BD12: =IF(ISNUMBER(FIND("Winner",Results!J15)),Setup!C$42,IF(ISNUMBER(FIND("2nd Place",Results!J15)),Setup!C$43,IF(ISNUMBER(FIND("3rd Place",Results!J15)),Setup!C$44,""))) | BG12: =SUM(F12:O12) -> 10 | BH12: =SUM(P12:T12)+BG12 -> 16
U13: =A13 -> 0 | BG13: =SUM(F13:O13) -> 0 | BH13: =SUM(P13:T13)+BG13 -> 0
A14: =Setup!B14 -> Tony W | B14: =SUM(F14:I14) -> 0 | C14: =SUM(J14:O14) -> 3 | D14: =SUM(P14:T14) -> 0 | E14: =N44 -> 0 | F14: ='Day 1 - Match 1'!O18 -> 0 | G14: ='Day 1 - Match 2'!O18 -> 0 | H14: ='Day 1 - Match 3'!O18 -> 0 | I14: =F44 -> 0 | J14: ='Day 2A - Match 4'!O18 -> 1 | K14: ='Day 2A - Match 5'!O18 -> 0 | L14: ='Day 2A - Match 6'!O18 -> 0 | M14: ='Day 2B - Match 7'!O18 -> 0 | N14: ='Day 2B - Match 8'!O18 -> 2 | O14: ='Day 2B - Match 9'!O18 -> 0 | P14: ='Day 3 - Match 10'!O18 -> 0 | Q14: ='Day 3 - Match 11'!O18 -> 0 | R14: ='Day 3 - Match 12'!O18 -> 0 | S14: =J44 -> 0 | T14: =Scramble!AG18 -> 0 | U14: =A14 -> Tony W | AB14: 7 | AC14: =COUNTIF($M$38:$M$53,AB14) -> 1 | AD14: =Setup!C55 -> 4 | AE14: =IF($AC14=AE$1,$AD14,0) -> 4 | AF14: =IF($AC14=$AF$1,SUM($AD14:$AD16)/$AF$1,0) -> 0 | AG14: =IF($AC14=$AG$1,SUM($AD14:$AD18)/$AG$1,0) -> 0 | AH14: =IF($AC14=$AH$1,SUM($AD14:$AD20)/$AH$1,0) -> 0 | AI14: =IF($AC14=AI$1,SUM($AD14:$AD22)/AI$1,0) -> 0 | AJ14: =IF($AC14=AJ$1,SUM($AD14:$AD24)/AJ$1,0) -> 0 | AK14: =IF($AC14=AK$1,SUM($AD14:$AD26)/AK$1,0) -> 0 | AO14: =COUNTIF(Results!R$5:R$36,AB14) -> 1 | AU14: =IF(Results!$R17=$AB$2,Results!AV17,"") | AV14: =IF(Results!$R17=$AB$4,Results!AW17,"") | AW14: =IF(Results!$R17=$AB$6,Results!AX17,"") | AX14: =IF(Results!$R17=$AB$8,Results!AY17,"") | AY14: =IF(Results!R17=AB$2,"Winner","") | AZ14: =IF(Results!R17=AB$4,"2nd Place","") | BA14: =IF(Results!R17=AB$6,"3rd Place","") | BB14: =IF(Results!R17=AB$8,"4th Place","") | BD14: =IF(ISNUMBER(FIND("Winner",Results!J17)),Setup!C$42,IF(ISNUMBER(FIND("2nd Place",Results!J17)),Setup!C$43,IF(ISNUMBER(FIND("3rd Place",Results!J17)),Setup!C$44,""))) | BG14: =SUM(F14:O14) -> 3 | BH14: =SUM(P14:T14)+BG14 -> 3
U15: =A15 -> 0 | BG15: =SUM(F15:O15) -> 0 | BH15: =SUM(P15:T15)+BG15 -> 0
A16: =Setup!B16 -> Manny | B16: =SUM(F16:I16) -> 2 | C16: =SUM(J16:O16) -> 5 | D16: =SUM(P16:T16) -> 1 | E16: =N45 -> 3 | F16: ='Day 1 - Match 1'!O20 -> 2 | G16: ='Day 1 - Match 2'!O20 -> 0 | H16: ='Day 1 - Match 3'!O20 -> 0 | I16: =F45 -> 0 | J16: ='Day 2A - Match 4'!O20 -> 2 | K16: ='Day 2A - Match 5'!O20 -> 0 | L16: ='Day 2A - Match 6'!O20 -> 1 | M16: ='Day 2B - Match 7'!O20 -> 2 | N16: ='Day 2B - Match 8'!O20 -> 0 | O16: ='Day 2B - Match 9'!O20 -> 0 | P16: ='Day 3 - Match 10'!O20 -> 0 | Q16: ='Day 3 - Match 11'!O20 -> 0 | R16: ='Day 3 - Match 12'!O20 -> 0 | S16: =J45 -> 0 | T16: =Scramble!AG20 -> 1 | U16: =A16 -> Manny | AB16: 8 | AC16: =COUNTIF($M$38:$M$53,AB16) -> 1 | AD16: =Setup!C56 -> 3 | AE16: =IF($AC16=AE$1,$AD16,0) -> 3 | AF16: =IF($AC16=$AF$1,SUM($AD16:$AD18)/$AF$1,0) -> 0 | AG16: =IF($AC16=$AG$1,SUM($AD16:$AD20)/$AG$1,0) -> 0 | AH16: =IF($AC16=$AH$1,SUM($AD16:$AD22)/$AH$1,0) -> 0 | AI16: =IF($AC16=AI$1,SUM($AD16:$AD24)/AI$1,0) -> 0 | AJ16: =IF($AC16=AJ$1,SUM($AD16:$AD26)/AJ$1,0) -> 0 | AK16: =IF($AC16=AK$1,SUM($AD16:$AD28)/AK$1,0) -> 0 | AO16: =COUNTIF(Results!R$5:R$36,AB16) -> 1 | AU16: =IF(Results!$R19=$AB$2,Results!AV19,"") | AV16: =IF(Results!$R19=$AB$4,Results!AW19,"") | AW16: =IF(Results!$R19=$AB$6,Results!AX19,"") | AX16: =IF(Results!$R19=$AB$8,Results!AY19,"") | AY16: =IF(Results!R19=AB$2,"Winner","") | AZ16: =IF(Results!R19=AB$4,"2nd Place","") | BA16: =IF(Results!R19=AB$6,"3rd Place","") | BB16: =IF(Results!R19=AB$8,"4th Place","") | BD16: =IF(ISNUMBER(FIND("Winner",Results!J19)),Setup!C$42,IF(ISNUMBER(FIND("2nd Place",Results!J19)),Setup!C$43,IF(ISNUMBER(FIND("3rd Place",Results!J19)),Setup!C$44,""))) | BG16: =SUM(F16:O16) -> 7 | BH16: =SUM(P16:T16)+BG16 -> 8
U17: =A17 -> 0 | BG17: =SUM(F17:O17) -> 0 | BH17: =SUM(P17:T17)+BG17 -> 0
A18: =Setup!B18 -> Tommy | B18: =SUM(F18:I18) -> 8 | C18: =SUM(J18:O18) -> 11 | D18: =SUM(P18:T18) -> 7 | E18: =N46 -> 6.625 | F18: ='Day 1 - Match 1'!O22 -> 2 | G18: ='Day 1 - Match 2'!O22 -> 2 | H18: ='Day 1 - Match 3'!O22 -> 2 | I18: =F46 -> 2 | J18: ='Day 2A - Match 4'!O22 -> 2 | K18: ='Day 2A - Match 5'!O22 -> 1 | L18: ='Day 2A - Match 6'!O22 -> 2 | M18: ='Day 2B - Match 7'!O22 -> 2 | N18: ='Day 2B - Match 8'!O22 -> 2 | O18: ='Day 2B - Match 9'!O22 -> 2 | P18: ='Day 3 - Match 10'!O22 -> 2 | Q18: ='Day 3 - Match 11'!O22 -> 0 | R18: ='Day 3 - Match 12'!O22 -> 2 | S18: =J46 -> 2 | T18: =Scramble!AG22 -> 1 | U18: =A18 -> Tommy | AB18: 9 | AC18: =COUNTIF($M$38:$M$53,AB18) -> 4 | AD18: =Setup!C57 -> 0 | AE18: =IF($AC18=AE$1,$AD18,0) -> 0 | AF18: =IF($AC18=$AF$1,SUM($AD18:$AD20)/$AF$1,0) -> 0 | AG18: =IF($AC18=$AG$1,SUM($AD18:$AD22)/$AG$1,0) -> 0 | AH18: =IF($AC18=$AH$1,SUM($AD18:$AD24)/$AH$1,0) -> 0 | AI18: =IF($AC18=AI$1,SUM($AD18:$AD26)/AI$1,0) -> 0 | AJ18: =IF($AC18=AJ$1,SUM($AD18:$AD28)/AJ$1,0) -> 0 | AK18: =IF($AC18=AK$1,SUM($AD18:$AD30)/AK$1,0) -> 0 | AO18: =COUNTIF(Results!R$5:R$36,AB18) -> 1 | AU18: =IF(Results!$R21=$AB$2,Results!AV21,"") | AV18: =IF(Results!$R21=$AB$4,Results!AW21,"") -> 350 | AW18: =IF(Results!$R21=$AB$6,Results!AX21,"") | AX18: =IF(Results!$R21=$AB$8,Results!AY21,"") | AY18: =IF(Results!R21=AB$2,"Winner","") | AZ18: =IF(Results!R21=AB$4,"2nd Place","") -> 2nd Place | BA18: =IF(Results!R21=AB$6,"3rd Place","") | BB18: =IF(Results!R21=AB$8,"4th Place","") | BD18: =IF(ISNUMBER(FIND("Winner",Results!J21)),Setup!C$42,IF(ISNUMBER(FIND("2nd Place",Results!J21)),Setup!C$43,IF(ISNUMBER(FIND("3rd Place",Results!J21)),Setup!C$44,""))) -> 350 | BG18: =SUM(F18:O18) -> 19 | BH18: =SUM(P18:T18)+BG18 -> 26
U19: =A19 -> 0 | BG19: =SUM(F19:O19) -> 0 | BH19: =SUM(P19:T19)+BG19 -> 0
A20: =Setup!B20 -> Dave | B20: =SUM(F20:I20) -> 6 | C20: =SUM(J20:O20) -> 7 | D20: =SUM(P20:T20) -> 1 | E20: =N47 -> 5 | F20: ='Day 1 - Match 1'!O24 -> 0 | G20: ='Day 1 - Match 2'!O24 -> 2 | H20: ='Day 1 - Match 3'!O24 -> 2 | I20: =F47 -> 2 | J20: ='Day 2A - Match 4'!O24 -> 2 | K20: ='Day 2A - Match 5'!O24 -> 1 | L20: ='Day 2A - Match 6'!O24 -> 2 | M20: ='Day 2B - Match 7'!O24 -> 0 | N20: ='Day 2B - Match 8'!O24 -> 2 | O20: ='Day 2B - Match 9'!O24 -> 0 | P20: ='Day 3 - Match 10'!O24 -> 0 | Q20: ='Day 3 - Match 11'!O24 -> 0 | R20: ='Day 3 - Match 12'!O24 -> 1 | S20: =J47 -> 0 | T20: =Scramble!AG24 -> 0 | U20: =A20 -> Dave | AB20: 10 | AC20: =COUNTIF($M$38:$M$53,AB20) -> 0 | AD20: =Setup!C58 -> 0 | AE20: =IF($AC20=AE$1,$AD20,0) -> 0 | AF20: =IF($AC20=$AF$1,SUM($AD20:$AD22)/$AF$1,0) -> 0 | AG20: =IF($AC20=$AG$1,SUM($AD20:$AD24)/$AG$1,0) -> 0 | AH20: =IF($AC20=$AH$1,SUM($AD20:$AD26)/$AH$1,0) -> 0 | AI20: =IF($AC20=AI$1,SUM($AD20:$AD28)/AI$1,0) -> 0 | AJ20: =IF($AC20=AJ$1,SUM($AD20:$AD30)/AJ$1,0) -> 0 | AK20: =IF($AC20=AK$1,SUM($AD20:$AD32)/AK$1,0) -> 0 | AO20: =COUNTIF(Results!R$5:R$36,AB20) -> 1 | AU20: =IF(Results!$R23=$AB$2,Results!AV23,"") | AV20: =IF(Results!$R23=$AB$4,Results!AW23,"") | AW20: =IF(Results!$R23=$AB$6,Results!AX23,"") | AX20: =IF(Results!$R23=$AB$8,Results!AY23,"") | AY20: =IF(Results!R23=AB$2,"Winner","") | AZ20: =IF(Results!R23=AB$4,"2nd Place","") | BA20: =IF(Results!R23=AB$6,"3rd Place","") | BB20: =IF(Results!R23=AB$8,"4th Place","") | BD20: =IF(ISNUMBER(FIND("Winner",Results!J23)),Setup!C$42,IF(ISNUMBER(FIND("2nd Place",Results!J23)),Setup!C$43,IF(ISNUMBER(FIND("3rd Place",Results!J23)),Setup!C$44,""))) | BG20: =SUM(F20:O20) -> 13 | BH20: =SUM(P20:T20)+BG20 -> 14
U21: =A21 -> 0 | BG21: =SUM(F21:O21) -> 0 | BH21: =SUM(P21:T21)+BG21 -> 0
A22: =Setup!B22 -> Hunter | B22: =SUM(F22:I22) -> 2 | C22: =SUM(J22:O22) -> 9 | D22: =SUM(P22:T22) -> 9 | E22: =N48 -> 0 | F22: ='Day 1 - Match 1'!O26 -> 2 | G22: ='Day 1 - Match 2'!O26 -> 0 | H22: ='Day 1 - Match 3'!O26 -> 0 | I22: =F48 -> 0 | J22: ='Day 2A - Match 4'!O26 -> 0 | K22: ='Day 2A - Match 5'!O26 -> 2 | L22: ='Day 2A - Match 6'!O26 -> 2 | M22: ='Day 2B - Match 7'!O26 -> 2 | N22: ='Day 2B - Match 8'!O26 -> 2 | O22: ='Day 2B - Match 9'!O26 -> 1 | P22: ='Day 3 - Match 10'!O26 -> 1 | Q22: ='Day 3 - Match 11'!O26 -> 2 | R22: ='Day 3 - Match 12'!O26 -> 2 | S22: =J48 -> 2 | T22: =Scramble!AG26 -> 2 | U22: =A22 -> Hunter | AB22: 11 | AC22: =COUNTIF($M$38:$M$53,AB22) -> 0 | AD22: =Setup!C59 -> 0 | AE22: =IF($AC22=AE$1,$AD22,0) -> 0 | AF22: =IF($AC22=$AF$1,SUM($AD22:$AD24)/$AF$1,0) -> 0 | AG22: =IF($AC22=$AG$1,SUM($AD22:$AD26)/$AG$1,0) -> 0 | AH22: =IF($AC22=$AH$1,SUM($AD22:$AD28)/$AH$1,0) -> 0 | AI22: =IF($AC22=AI$1,SUM($AD22:$AD30)/AI$1,0) -> 0 | AJ22: =IF($AC22=AJ$1,SUM($AD22:$AD32)/AJ$1,0) -> 0 | AK22: =IF($AC22=AK$1,SUM($AD22:$AD33)/AK$1,0) -> 0 | AO22: =COUNTIF(Results!R$5:R$36,AB22) -> 1 | AU22: =IF(Results!$R25=$AB$2,Results!AV25,"") | AV22: =IF(Results!$R25=$AB$4,Results!AW25,"") | AW22: =IF(Results!$R25=$AB$6,Results!AX25,"") | AX22: =IF(Results!$R25=$AB$8,Results!AY25,"") | AY22: =IF(Results!R25=AB$2,"Winner","") | AZ22: =IF(Results!R25=AB$4,"2nd Place","") | BA22: =IF(Results!R25=AB$6,"3rd Place","") | BB22: =IF(Results!R25=AB$8,"4th Place","") | BD22: =IF(ISNUMBER(FIND("Winner",Results!J25)),Setup!C$42,IF(ISNUMBER(FIND("2nd Place",Results!J25)),Setup!C$43,IF(ISNUMBER(FIND("3rd Place",Results!J25)),Setup!C$44,""))) | BG22: =SUM(F22:O22) -> 11 | BH22: =SUM(P22:T22)+BG22 -> 20
U23: =A23 -> 0 | BG23: =SUM(F23:O23) -> 0 | BH23: =SUM(P23:T23)+BG23 -> 0
A24: =Setup!B24 -> Gerald C | B24: =SUM(F24:I24) -> 0 | C24: =SUM(J24:O24) -> 2 | D24: =SUM(P24:T24) -> 7 | E24: =N49 -> 0 | F24: ='Day 1 - Match 1'!O28 -> 0 | G24: ='Day 1 - Match 2'!O28 -> 0 | H24: ='Day 1 - Match 3'!O28 -> 0 | I24: =F49 -> 0 | J24: ='Day 2A - Match 4'!O28 -> 0 | K24: ='Day 2A - Match 5'!O28 -> 2 | L24: ='Day 2A - Match 6'!O28 -> 0 | M24: ='Day 2B - Match 7'!O28 -> 0 | N24: ='Day 2B - Match 8'!O28 -> 0 | O24: ='Day 2B - Match 9'!O28 -> 0 | P24: ='Day 3 - Match 10'!O28 -> 0 | Q24: ='Day 3 - Match 11'!O28 -> 2 | R24: ='Day 3 - Match 12'!O28 -> 2 | S24: =J49 -> 0 | T24: =Scramble!AG28 -> 3 | U24: =A24 -> Gerald C | AB24: 12 | AC24: =COUNTIF($M$38:$M$53,AB24) -> 0 | AD24: =Setup!C60 -> 0 | AE24: =IF($AC24=AE$1,$AD24,0) -> 0 | AF24: =IF($AC24=$AF$1,SUM($AD24:$AD26)/$AF$1,0) -> 0 | AG24: =IF($AC24=$AG$1,SUM($AD24:$AD28)/$AG$1,0) -> 0 | AH24: =IF($AC24=$AH$1,SUM($AD24:$AD30)/$AH$1,0) -> 0 | AI24: =IF($AC24=AI$1,SUM($AD24:$AD32)/AI$1,0) -> 0 | AJ24: =IF($AC24=AJ$1,SUM($AD24:$AD33)/AJ$1,0) -> 0 | AK24: =IF($AC24=AK$1,SUM($AD24:$AD33)/AK$1,0) -> 0 | AO24: =COUNTIF(Results!R$5:R$36,AB24) -> 1 | AU24: =IF(Results!$R27=$AB$2,Results!AV27,"") | AV24: =IF(Results!$R27=$AB$4,Results!AW27,"") | AW24: =IF(Results!$R27=$AB$6,Results!AX27,"") | AX24: =IF(Results!$R27=$AB$8,Results!AY27,"") | AY24: =IF(Results!R27=AB$2,"Winner","") | AZ24: =IF(Results!R27=AB$4,"2nd Place","") | BA24: =IF(Results!R27=AB$6,"3rd Place","") | BB24: =IF(Results!R27=AB$8,"4th Place","") | BD24: =IF(ISNUMBER(FIND("Winner",Results!J27)),Setup!C$42,IF(ISNUMBER(FIND("2nd Place",Results!J27)),Setup!C$43,IF(ISNUMBER(FIND("3rd Place",Results!J27)),Setup!C$44,""))) | BG24: =SUM(F24:O24) -> 2 | BH24: =SUM(P24:T24)+BG24 -> 9
U25: =A25 -> 0 | BG25: =SUM(F25:O25) -> 0 | BH25: =SUM(P25:T25)+BG25 -> 0
A26: =Setup!B26 -> Bob | B26: =SUM(F26:I26) -> 6 | C26: =SUM(J26:O26) -> 8 | D26: =SUM(P26:T26) -> 4 | E26: =N50 -> 10 | F26: ='Day 1 - Match 1'!O30 -> 2 | G26: ='Day 1 - Match 2'!O30 -> 2 | H26: ='Day 1 - Match 3'!O30 -> 2 | I26: =F50 -> 0 | J26: ='Day 2A - Match 4'!O30 -> 0 | K26: ='Day 2A - Match 5'!O30 -> 2 | L26: ='Day 2A - Match 6'!O30 -> 2 | M26: ='Day 2B - Match 7'!O30 -> 2 | N26: ='Day 2B - Match 8'!O30 -> 0 | O26: ='Day 2B - Match 9'!O30 -> 2 | P26: ='Day 3 - Match 10'!O30 -> 2 | Q26: ='Day 3 - Match 11'!O30 -> 0 | R26: ='Day 3 - Match 12'!O30 -> 0 | S26: =J50 -> 0 | T26: =Scramble!AG30 -> 2 | U26: =A26 -> Bob | AB26: 13 | AC26: =COUNTIF($M$38:$M$53,AB26) -> 1 | AD26: =Setup!C61 -> 0 | AE26: =IF($AC26=AE$1,$AD26,0) -> 0 | AF26: =IF($AC26=$AF$1,SUM($AD26:$AD28)/$AF$1,0) -> 0 | AG26: =IF($AC26=$AG$1,SUM($AD26:$AD30)/$AG$1,0) -> 0 | AH26: =IF($AC26=$AH$1,SUM($AD26:$AD32)/$AH$1,0) -> 0 | AI26: =IF($AC26=AI$1,SUM($AD26:$AD33)/AI$1,0) -> 0 | AJ26: =IF($AC26=AJ$1,SUM($AD26:$AD33)/AJ$1,0) -> 0 | AK26: =IF($AC26=AK$1,SUM($AD26:$AD33)/AK$1,0) -> 0 | AO26: =COUNTIF(Results!R$5:R$36,AB26) -> 1 | AU26: =IF(Results!$R29=$AB$2,Results!AV29,"") | AV26: =IF(Results!$R29=$AB$4,Results!AW29,"") | AW26: =IF(Results!$R29=$AB$6,Results!AX29,"") | AX26: =IF(Results!$R29=$AB$8,Results!AY29,"") -> 0 | AY26: =IF(Results!R29=AB$2,"Winner","") | AZ26: =IF(Results!R29=AB$4,"2nd Place","") | BA26: =IF(Results!R29=AB$6,"3rd Place","") | BB26: =IF(Results!R29=AB$8,"4th Place","") -> 4th Place | BD26: =IF(ISNUMBER(FIND("Winner",Results!J29)),Setup!C$42,IF(ISNUMBER(FIND("2nd Place",Results!J29)),Setup!C$43,IF(ISNUMBER(FIND("3rd Place",Results!J29)),Setup!C$44,""))) | BG26: =SUM(F26:O26) -> 14 | BH26: =SUM(P26:T26)+BG26 -> 18
U27: =A27 -> 0 | BG27: =SUM(F27:O27) -> 0 | BH27: =SUM(P27:T27)+BG27 -> 0
A28: =Setup!B28 -> Patrick | B28: =SUM(F28:I28) -> 0 | C28: =SUM(J28:O28) -> 2 | D28: =SUM(P28:T28) -> 5 | E28: =N51 -> 0 | F28: ='Day 1 - Match 1'!O32 -> 0 | G28: ='Day 1 - Match 2'!O32 -> 0 | H28: ='Day 1 - Match 3'!O32 -> 0 | I28: =F51 -> 0 | J28: ='Day 2A - Match 4'!O32 -> 0 | K28: ='Day 2A - Match 5'!O32 -> 2 | L28: ='Day 2A - Match 6'!O32 -> 0 | M28: ='Day 2B - Match 7'!O32 -> 0 | N28: ='Day 2B - Match 8'!O32 -> 0 | O28: ='Day 2B - Match 9'!O32 -> 0 | P28: ='Day 3 - Match 10'!O32 -> 2 | Q28: ='Day 3 - Match 11'!O32 -> 0 | R28: ='Day 3 - Match 12'!O32 -> 0 | S28: =J51 -> 0 | T28: =Scramble!AG32 -> 3 | U28: =A28 -> Patrick | AB28: 14 | AC28: =COUNTIF($M$38:$M$53,AB28) -> 1 | AD28: =Setup!C62 -> 0 | AE28: =IF($AC28=AE$1,$AD28,0) -> 0 | AF28: =IF($AC28=$AF$1,SUM($AD28:$AD30)/$AF$1,0) -> 0 | AG28: =IF($AC28=$AG$1,SUM($AD28:$AD32)/$AG$1,0) -> 0 | AH28: =IF($AC28=$AH$1,SUM($AD28:$AD33)/$AH$1,0) -> 0 | AI28: =IF($AC28=AI$1,SUM($AD28:$AD33)/AI$1,0) -> 0 | AJ28: =IF($AC28=AJ$1,SUM($AD28:$AD33)/AJ$1,0) -> 0 | AK28: =IF($AC28=AK$1,SUM($AD28:$AD33)/AK$1,0) -> 0 | AO28: =COUNTIF(Results!R$5:R$36,AB28) -> 1 | AU28: =IF(Results!$R31=$AB$2,Results!AV31,"") | AV28: =IF(Results!$R31=$AB$4,Results!AW31,"") | AW28: =IF(Results!$R31=$AB$6,Results!AX31,"") | AX28: =IF(Results!$R31=$AB$8,Results!AY31,"") | AY28: =IF(Results!R31=AB$2,"Winner","") | AZ28: =IF(Results!R31=AB$4,"2nd Place","") | BA28: =IF(Results!R31=AB$6,"3rd Place","") | BB28: =IF(Results!R31=AB$8,"4th Place","") | BD28: =IF(ISNUMBER(FIND("Winner",Results!J31)),Setup!C$42,IF(ISNUMBER(FIND("2nd Place",Results!J31)),Setup!C$43,IF(ISNUMBER(FIND("3rd Place",Results!J31)),Setup!C$44,""))) | BG28: =SUM(F28:O28) -> 2 | BH28: =SUM(P28:T28)+BG28 -> 7
U29: =A29 -> 0 | BG29: =SUM(F29:O29) -> 0 | BH29: =SUM(P29:T29)+BG29 -> 0
A30: =Setup!B30 -> Brian S | B30: =SUM(F30:I30) -> 6 | C30: =SUM(J30:O30) -> 5 | D30: =SUM(P30:T30) -> 7 | E30: =N52 -> 0 | F30: ='Day 1 - Match 1'!O34 -> 2 | G30: ='Day 1 - Match 2'!O34 -> 0 | H30: ='Day 1 - Match 3'!O34 -> 2 | I30: =F52 -> 2 | J30: ='Day 2A - Match 4'!O34 -> 1 | K30: ='Day 2A - Match 5'!O34 -> 0 | L30: ='Day 2A - Match 6'!O34 -> 0 | M30: ='Day 2B - Match 7'!O34 -> 0 | N30: ='Day 2B - Match 8'!O34 -> 2 | O30: ='Day 2B - Match 9'!O34 -> 2 | P30: ='Day 3 - Match 10'!O34 -> 2 | Q30: ='Day 3 - Match 11'!O34 -> 2 | R30: ='Day 3 - Match 12'!O34 -> 2 | S30: =J52 -> 0 | T30: =Scramble!AG34 -> 1 | U30: =A30 -> Brian S | AB30: 15 | AC30: =COUNTIF($M$38:$M$53,AB30) -> 1 | AD30: =Setup!C63 -> 0 | AE30: =IF($AC30=AE$1,$AD30,0) -> 0 | AF30: =IF($AC30=$AF$1,SUM($AD30:$AD32)/$AF$1,0) -> 0 | AG30: =IF($AC30=$AG$1,SUM($AD30:$AD33)/$AG$1,0) -> 0 | AH30: =IF($AC30=$AH$1,SUM($AD30:$AD33)/$AH$1,0) -> 0 | AI30: =IF($AC30=AI$1,SUM($AD30:$AD33)/AI$1,0) -> 0 | AJ30: =IF($AC30=AJ$1,SUM($AD30:$AD33)/AJ$1,0) -> 0 | AK30: =IF($AC30=AK$1,SUM($AD30:$AD33)/AK$1,0) -> 0 | AO30: =COUNTIF(Results!R$5:R$36,AB30) -> 1 | AU30: =IF(Results!$R33=$AB$2,Results!AV33,"") | AV30: =IF(Results!$R33=$AB$4,Results!AW33,"") | AW30: =IF(Results!$R33=$AB$6,Results!AX33,"") | AX30: =IF(Results!$R33=$AB$8,Results!AY33,"") | AY30: =IF(Results!R33=AB$2,"Winner","") | AZ30: =IF(Results!R33=AB$4,"2nd Place","") | BA30: =IF(Results!R33=AB$6,"3rd Place","") | BB30: =IF(Results!R33=AB$8,"4th Place","") | BD30: =IF(ISNUMBER(FIND("Winner",Results!J37)),Setup!C$42,IF(ISNUMBER(FIND("2nd Place",Results!J37)),Setup!C$43,IF(ISNUMBER(FIND("3rd Place",Results!J37)),Setup!C$44,""))) | BG30: =SUM(F30:O30) -> 11 | BH30: =SUM(P30:T30)+BG30 -> 18
U31: =A31 -> 0 | BG31: =SUM(F31:O31) -> 0 | BH31: =SUM(P31:T31)+BG31 -> 0
A32: =Setup!B32 -> Chris | B32: =SUM(F32:I32) -> 2 | C32: =SUM(J32:O32) -> 6 | D32: =SUM(P32:T32) -> 4 | E32: =N53 -> 0 | F32: ='Day 1 - Match 1'!O36 -> 0 | G32: ='Day 1 - Match 2'!O36 -> 2 | H32: ='Day 1 - Match 3'!O36 -> 0 | I32: =F53 -> 0 | J32: ='Day 2A - Match 4'!O36 -> 0 | K32: ='Day 2A - Match 5'!O36 -> 2 | L32: ='Day 2A - Match 6'!O36 -> 2 | M32: ='Day 2B - Match 7'!O36 -> 0 | N32: ='Day 2B - Match 8'!O36 -> 0 | O32: ='Day 2B - Match 9'!O36 -> 2 | P32: ='Day 3 - Match 10'!O36 -> 0 | Q32: ='Day 3 - Match 11'!O36 -> 2 | R32: ='Day 3 - Match 12'!O36 -> 0 | S32: =J53 -> 2 | T32: =Scramble!AG36 -> 0 | U32: =A32 -> Chris | AB32: 16 | AC32: =COUNTIF($M$38:$M$53,AB32) -> 1 | AD32: =Setup!C64 -> 0 | AE32: =IF($AC32=AE$1,$AD32,0) -> 0 | AF32: =IF($AC32=$AF$1,SUM($AD32:$AD33)/$AF$1,0) -> 0 | AG32: =IF($AC32=$AG$1,SUM($AD32:$AD33)/$AG$1,0) -> 0 | AH32: =IF($AC32=$AH$1,SUM($AD32:$AD33)/$AH$1,0) -> 0 | AI32: =IF($AC32=AI$1,SUM($AD32:$AD33)/AI$1,0) -> 0 | AJ32: =IF($AC32=AJ$1,SUM($AD32:$AD33)/AJ$1,0) -> 0 | AK32: =IF($AC32=AK$1,SUM($AD32:$AD33)/AK$1,0) -> 0 | AO32: =COUNTIF(Results!R$5:R$36,AB32) -> 1 | AU32: =IF(Results!$R35=$AB$2,Results!AV35,"") | AV32: =IF(Results!$R35=$AB$4,Results!AW35,"") | AW32: =IF(Results!$R35=$AB$6,Results!AX35,"") | AX32: =IF(Results!$R35=$AB$8,Results!AY35,"") | AY32: =IF(Results!R35=AB$2,"Winner","") | AZ32: =IF(Results!R35=AB$4,"2nd Place","") | BA32: =IF(Results!R35=AB$6,"3rd Place","") | BB32: =IF(Results!R35=AB$8,"4th Place","") | BD32: =IF(ISNUMBER(FIND("Winner",Results!J39)),Setup!C$42,IF(ISNUMBER(FIND("2nd Place",Results!J39)),Setup!C$43,IF(ISNUMBER(FIND("3rd Place",Results!J39)),Setup!C$44,""))) | BG32: =SUM(F32:O32) -> 8 | BH32: =SUM(P32:T32)+BG32 -> 12
A34: Totals | B34: =SUM(B2:B32) -> 64 | C34: =SUM(C2:C32) -> 96 | D34: =SUM(D2:D32) -> 88 | E34: =SUM(E2:E32) -> 55.75 | F34: =SUM(F2:F32) -> 16 | G34: =SUM(G2:G32) -> 16 | H34: =SUM(H2:H32) -> 16 | I34: =SUM(I2:I32) -> 16 | ... T34: =SUM(T2:T32) -> 24 | BD34: =IF(ISNUMBER(FIND("Winner",Results!#REF!)),Setup!C$42,IF(ISNUMBER(FIND("2nd Place",Results!#REF!)),Setup!C$43,IF(ISNUMBER(FIND("3rd Place",Results!#REF!)),Setup!C$44,"")))
A36: Stroke Play Calculations | C36: Day 1 | G36: Day 3 | K36: Day 4
A37: Player | B37: Handicap | C37: Score | D37: Net | E37: Rank | F37: Points | G37: Score | H37: Net | I37: Rank | J37: Points | K37: Score | L37: Net | M37: Rank | N37: Points
A38: =A2 -> Mil | B38: =ROUND(Setup!I2,0) -> 12 | C38: =SUM('Day 1 - Match 1:Day 1 - Match 2'!$N6) -> 87 | D38: =C38-$B38 -> 75 | E38: =RANK(D38,D$38:D$53,1) -> 3 | F38: =IF(E38<9,2,0) -> 2 | G38: =SUM('Day 3 - Match 10:Day 3 - Match 11'!N6) -> 91 | H38: =G38-($B38) -> 79 | I38: =RANK(H38,H$38:H$53,1) -> 9 | J38: =IF(I38<9,2,0) -> 0 | K38: ='Day 4 - Front 9'!N6+'Day 4 - Back 9'!N6 -> 101 | L38: =K38-B38 -> 89 | M38: =RANK(L38,L$38:L$53,1) -> 13 | N38: =SUM(AE38:AN38) -> 0 | AE38: =IF(AE$1=$M38,SUM($AE$2:$AK$2),0) -> 0 | AF38: =IF(AF$1=$M38,SUM($AE$4:$AI$4),0) -> 0 | AG38: =IF(AG$1=$M38,SUM($AE$6:$AI$6),0) -> 0 | AH38: =IF(AH$1=$M38,SUM($AE$8:$AI$8),0) -> 0 | AI38: =IF(AI$1=$M38,SUM($AE$10:$AI$10),0) -> 0 | AJ38: =IF(AJ$1=$M38,SUM($AE$12:$AI$12),0) -> 0 | AK38: =IF(AK$1=$M38,SUM($AE$14:$AI$14),0) -> 0 | AL38: =IF(AL$1=$M38,SUM($AE$16:$AI$16),0) -> 0 | AM38: =IF(AM$1=$M38,SUM($AE$18:$AI$18),0) -> 0 | AN38: =IF(AN$1=$M38,SUM($AE$20:$AI$20),0) -> 0
